{
  "version": 8,
  "blockIdVersion": 10,
  "anchorX": 0,
  "anchorY": 0,
  "anchorZ": 0,
  "blocks": [
    {
      "x": -10,
      "y": 21,
      "z": -1,
      "name": "Empty"
    },
    {
      "x": -9,
      "y": 21,
      "z": -1,
      "name": "Empty"
    },
    {
      "x": -8,
      "y": 19,
      "z": -8,
      "name": "Empty"
    },
    {
      "x": -8,
      "y": 20,
      "z": -7,
      "name": "Empty"
    },
    {
      "x": -8,
      "y": 18,
      "z": -2,
      "name": "Empty"
    },
    {
      "x": -8,
      "y": 18,
      "z": -1,
      "name": "Empty"
    },
    {
      "x": -8,
      "y": 21,
      "z": -1,
      "name": "Empty"
    },
    {
      "x": -8,
      "y": 22,
      "z": -1,
      "name": "Empty"
    },
    {
      "x": -8,
      "y": 26,
      "z": -1,
      "name": "Empty"
    },
    {
      "x": -7,
      "y": 20,
      "z": -8,
      "name": "Empty"
    },
    {
      "x": -7,
      "y": 20,
      "z": -7,
      "name": "Empty"
    },
    {
      "x": -7,
      "y": 21,
      "z": -6,
      "name": "Empty"
    },
    {
      "x": -7,
      "y": 18,
      "z": -2,
      "name": "Empty"
    },
    {
      "x": -7,
      "y": 18,
      "z": -1,
      "name": "Empty"
    },
    {
      "x": -7,
      "y": 22,
      "z": -1,
      "name": "Empty"
    },
    {
      "x": -7,
      "y": 26,
      "z": -1,
      "name": "Empty"
    },
    {
      "x": -7,
      "y": 25,
      "z": 5,
      "name": "Empty"
    },
    {
      "x": -7,
      "y": 25,
      "z": 6,
      "name": "Empty"
    },
    {
      "x": -6,
      "y": 21,
      "z": -7,
      "name": "Empty"
    },
    {
      "x": -6,
      "y": 21,
      "z": -6,
      "name": "Empty"
    },
    {
      "x": -6,
      "y": 21,
      "z": -5,
      "name": "Empty"
    },
    {
      "x": -6,
      "y": 21,
      "z": -4,
      "name": "Empty"
    },
    {
      "x": -6,
      "y": 18,
      "z": -2,
      "name": "Empty"
    },
    {
      "x": -6,
      "y": 22,
      "z": -2,
      "name": "Empty"
    },
    {
      "x": -6,
      "y": 25,
      "z": -2,
      "name": "Empty"
    },
    {
      "x": -6,
      "y": 17,
      "z": -1,
      "name": "Empty"
    },
    {
      "x": -6,
      "y": 18,
      "z": -1,
      "name": "Wood_Poisoned_Branch_Long",
      "rotation": 5
    },
    {
      "x": -6,
      "y": 22,
      "z": -1,
      "name": "Empty"
    },
    {
      "x": -6,
      "y": 25,
      "z": -1,
      "name": "Empty"
    },
    {
      "x": -6,
      "y": 26,
      "z": -1,
      "name": "Empty"
    },
    {
      "x": -6,
      "y": 29,
      "z": -1,
      "name": "Empty"
    },
    {
      "x": -6,
      "y": 33,
      "z": -1,
      "name": "Empty"
    },
    {
      "x": -6,
      "y": 16,
      "z": 0,
      "name": "Empty",
      "rotation": 8
    },
    {
      "x": -6,
      "y": 17,
      "z": 0,
      "name": "Empty"
    },
    {
      "x": -6,
      "y": 19,
      "z": 0,
      "name": "Empty"
    },
    {
      "x": -6,
      "y": 22,
      "z": 0,
      "name": "Empty"
    },
    {
      "x": -6,
      "y": 25,
      "z": 0,
      "name": "Empty"
    },
    {
      "x": -6,
      "y": 18,
      "z": 1,
      "name": "Empty"
    },
    {
      "x": -6,
      "y": 24,
      "z": 4,
      "name": "Empty"
    },
    {
      "x": -6,
      "y": 25,
      "z": 4,
      "name": "Empty"
    },
    {
      "x": -6,
      "y": 25,
      "z": 5,
      "name": "Empty"
    },
    {
      "x": -6,
      "y": 25,
      "z": 6,
      "name": "Empty"
    },
    {
      "x": -5,
      "y": -3,
      "z": -8,
      "name": "Wood_Poisoned_Trunk_Full"
    },
    {
      "x": -5,
      "y": -3,
      "z": -7,
      "name": "Wood_Poisoned_Trunk_Full"
    },
    {
      "x": -5,
      "y": 21,
      "z": -6,
      "name": "Empty"
    },
    {
      "x": -5,
      "y": 21,
      "z": -5,
      "name": "Empty"
    },
    {
      "x": -5,
      "y": 22,
      "z": -5,
      "name": "Empty"
    },
    {
      "x": -5,
      "y": 34,
      "z": -5,
      "name": "Empty"
    },
    {
      "x": -5,
      "y": 20,
      "z": -4,
      "name": "Empty"
    },
    {
      "x": -5,
      "y": 21,
      "z": -4,
      "name": "Empty"
    },
    {
      "x": -5,
      "y": 34,
      "z": -4,
      "name": "Empty"
    },
    {
      "x": -5,
      "y": 18,
      "z": -3,
      "name": "Empty"
    },
    {
      "x": -5,
      "y": 21,
      "z": -3,
      "name": "Empty"
    },
    {
      "x": -5,
      "y": 22,
      "z": -3,
      "name": "Empty"
    },
    {
      "x": -5,
      "y": 18,
      "z": -2,
      "name": "Empty"
    },
    {
      "x": -5,
      "y": 22,
      "z": -2,
      "name": "Empty"
    },
    {
      "x": -5,
      "y": 25,
      "z": -2,
      "name": "Empty"
    },
    {
      "x": -5,
      "y": 26,
      "z": -2,
      "name": "Empty"
    },
    {
      "x": -5,
      "y": 17,
      "z": -1,
      "name": "Empty"
    },
    {
      "x": -5,
      "y": 18,
      "z": -1,
      "name": "Wood_Poisoned_Trunk_Full"
    },
    {
      "x": -5,
      "y": 22,
      "z": -1,
      "name": "Empty"
    },
    {
      "x": -5,
      "y": 25,
      "z": -1,
      "name": "Wood_Poisoned_Branch_Long",
      "rotation": 5
    },
    {
      "x": -5,
      "y": 29,
      "z": -1,
      "name": "Empty"
    },
    {
      "x": -5,
      "y": 32,
      "z": -1,
      "name": "Wood_Poisoned_Branch_Long",
      "rotation": 5
    },
    {
      "x": -5,
      "y": 37,
      "z": -1,
      "name": "Empty"
    },
    {
      "x": -5,
      "y": 42,
      "z": -1,
      "name": "Empty"
    },
    {
      "x": -5,
      "y": 46,
      "z": -1,
      "name": "Empty"
    },
    {
      "x": -5,
      "y": 18,
      "z": 0,
      "name": "Empty"
    },
    {
      "x": -5,
      "y": 19,
      "z": 0,
      "name": "Empty"
    },
    {
      "x": -5,
      "y": 22,
      "z": 0,
      "name": "Empty"
    },
    {
      "x": -5,
      "y": 25,
      "z": 0,
      "name": "Empty"
    },
    {
      "x": -5,
      "y": 18,
      "z": 1,
      "name": "Empty"
    },
    {
      "x": -5,
      "y": 18,
      "z": 2,
      "name": "Empty"
    },
    {
      "x": -5,
      "y": 22,
      "z": 2,
      "name": "Empty"
    },
    {
      "x": -5,
      "y": 31,
      "z": 2,
      "name": "Empty"
    },
    {
      "x": -5,
      "y": 24,
      "z": 3,
      "name": "Empty"
    },
    {
      "x": -5,
      "y": 30,
      "z": 3,
      "name": "Empty"
    },
    {
      "x": -5,
      "y": -4,
      "z": 4,
      "name": "Wood_Poisoned_Trunk"
    },
    {
      "x": -5,
      "y": -3,
      "z": 4,
      "name": "Wood_Poisoned_Trunk"
    },
    {
      "x": -5,
      "y": -2,
      "z": 4,
      "name": "Wood_Poisoned_Trunk_Full"
    },
    {
      "x": -5,
      "y": 24,
      "z": 4,
      "name": "Empty"
    },
    {
      "x": -5,
      "y": -3,
      "z": 5,
      "name": "Wood_Poisoned_Trunk"
    },
    {
      "x": -5,
      "y": -2,
      "z": 5,
      "name": "Wood_Poisoned_Trunk_Full"
    },
    {
      "x": -5,
      "y": 24,
      "z": 5,
      "name": "Empty"
    },
    {
      "x": -5,
      "y": 25,
      "z": 5,
      "name": "Empty"
    },
    {
      "x": -4,
      "y": -3,
      "z": -8,
      "name": "Wood_Poisoned_Trunk_Full"
    },
    {
      "x": -4,
      "y": -3,
      "z": -7,
      "name": "Wood_Poisoned_Trunk"
    },
    {
      "x": -4,
      "y": -2,
      "z": -7,
      "name": "Wood_Poisoned_Trunk_Full"
    },
    {
      "x": -4,
      "y": -3,
      "z": -6,
      "name": "Wood_Poisoned_Trunk"
    },
    {
      "x": -4,
      "y": -2,
      "z": -6,
      "name": "Wood_Poisoned_Trunk_Full"
    },
    {
      "x": -4,
      "y": 21,
      "z": -6,
      "name": "Empty"
    },
    {
      "x": -4,
      "y": 20,
      "z": -5,
      "name": "Empty"
    },
    {
      "x": -4,
      "y": 21,
      "z": -5,
      "name": "Empty"
    },
    {
      "x": -4,
      "y": 34,
      "z": -5,
      "name": "Empty"
    },
    {
      "x": -4,
      "y": 18,
      "z": -4,
      "name": "Empty"
    },
    {
      "x": -4,
      "y": 19,
      "z": -4,
      "name": "Empty"
    },
    {
      "x": -4,
      "y": 20,
      "z": -4,
      "name": "Empty"
    },
    {
      "x": -4,
      "y": 21,
      "z": -4,
      "name": "Empty"
    },
    {
      "x": -4,
      "y": 22,
      "z": -4,
      "name": "Empty"
    },
    {
      "x": -4,
      "y": 35,
      "z": -4,
      "name": "Empty"
    },
    {
      "x": -4,
      "y": 18,
      "z": -3,
      "name": "Empty"
    },
    {
      "x": -4,
      "y": 20,
      "z": -3,
      "name": "Empty"
    },
    {
      "x": -4,
      "y": 21,
      "z": -3,
      "name": "Empty"
    },
    {
      "x": -4,
      "y": 22,
      "z": -3,
      "name": "Empty"
    },
    {
      "x": -4,
      "y": 35,
      "z": -3,
      "name": "Empty"
    },
    {
      "x": -4,
      "y": 18,
      "z": -2,
      "name": "Empty"
    },
    {
      "x": -4,
      "y": 21,
      "z": -2,
      "name": "Empty"
    },
    {
      "x": -4,
      "y": 22,
      "z": -2,
      "name": "Empty"
    },
    {
      "x": -4,
      "y": 25,
      "z": -2,
      "name": "Empty"
    },
    {
      "x": -4,
      "y": 32,
      "z": -2,
      "name": "Empty"
    },
    {
      "x": -4,
      "y": 35,
      "z": -2,
      "name": "Empty"
    },
    {
      "x": -4,
      "y": 37,
      "z": -2,
      "name": "Empty"
    },
    {
      "x": -4,
      "y": 42,
      "z": -2,
      "name": "Empty"
    },
    {
      "x": -4,
      "y": 17,
      "z": -1,
      "name": "Empty"
    },
    {
      "x": -4,
      "y": 18,
      "z": -1,
      "name": "Wood_Poisoned_Trunk_Full"
    },
    {
      "x": -4,
      "y": 19,
      "z": -1,
      "name": "Empty"
    },
    {
      "x": -4,
      "y": 22,
      "z": -1,
      "name": "Wood_Poisoned_Trunk_Full"
    },
    {
      "x": -4,
      "y": 25,
      "z": -1,
      "name": "Wood_Poisoned_Trunk_Full"
    },
    {
      "x": -4,
      "y": 29,
      "z": -1,
      "name": "Empty"
    },
    {
      "x": -4,
      "y": 32,
      "z": -1,
      "name": "Wood_Poisoned_Trunk_Full"
    },
    {
      "x": -4,
      "y": 37,
      "z": -1,
      "name": "Wood_Poisoned_Branch_Long",
      "rotation": 5
    },
    {
      "x": -4,
      "y": 42,
      "z": -1,
      "name": "Wood_Poisoned_Branch_Long",
      "rotation": 5
    },
    {
      "x": -4,
      "y": 43,
      "z": -1,
      "name": "Empty"
    },
    {
      "x": -4,
      "y": 46,
      "z": -1,
      "name": "Empty"
    },
    {
      "x": -4,
      "y": 7,
      "z": 0,
      "name": "Wood_Crystal_Branch_Short",
      "rotation": 3
    },
    {
      "x": -4,
      "y": 18,
      "z": 0,
      "name": "Empty"
    },
    {
      "x": -4,
      "y": 19,
      "z": 0,
      "name": "Empty"
    },
    {
      "x": -4,
      "y": 21,
      "z": 0,
      "name": "Empty",
      "rotation": 8
    },
    {
      "x": -4,
      "y": 22,
      "z": 0,
      "name": "Empty"
    },
    {
      "x": -4,
      "y": 25,
      "z": 0,
      "name": "Empty"
    },
    {
      "x": -4,
      "y": 29,
      "z": 0,
      "name": "Empty"
    },
    {
      "x": -4,
      "y": 31,
      "z": 0,
      "name": "Empty"
    },
    {
      "x": -4,
      "y": 37,
      "z": 0,
      "name": "Empty"
    },
    {
      "x": -4,
      "y": 41,
      "z": 0,
      "name": "Empty"
    },
    {
      "x": -4,
      "y": 46,
      "z": 0,
      "name": "Empty"
    },
    {
      "x": -4,
      "y": 18,
      "z": 1,
      "name": "Empty"
    },
    {
      "x": -4,
      "y": 22,
      "z": 1,
      "name": "Empty"
    },
    {
      "x": -4,
      "y": 24,
      "z": 1,
      "name": "Empty"
    },
    {
      "x": -4,
      "y": 25,
      "z": 1,
      "name": "Empty"
    },
    {
      "x": -4,
      "y": 28,
      "z": 1,
      "name": "Empty"
    },
    {
      "x": -4,
      "y": 31,
      "z": 1,
      "name": "Empty"
    },
    {
      "x": -4,
      "y": 18,
      "z": 2,
      "name": "Empty"
    },
    {
      "x": -4,
      "y": 22,
      "z": 2,
      "name": "Empty"
    },
    {
      "x": -4,
      "y": 24,
      "z": 2,
      "name": "Empty"
    },
    {
      "x": -4,
      "y": 31,
      "z": 2,
      "name": "Empty"
    },
    {
      "x": -4,
      "y": 40,
      "z": 2,
      "name": "Empty"
    },
    {
      "x": -4,
      "y": -2,
      "z": 3,
      "name": "Wood_Poisoned_Trunk"
    },
    {
      "x": -4,
      "y": -1,
      "z": 3,
      "name": "Wood_Poisoned_Trunk_Full"
    },
    {
      "x": -4,
      "y": 18,
      "z": 3,
      "name": "Empty"
    },
    {
      "x": -4,
      "y": 22,
      "z": 3,
      "name": "Empty"
    },
    {
      "x": -4,
      "y": 24,
      "z": 3,
      "name": "Empty"
    },
    {
      "x": -4,
      "y": 31,
      "z": 3,
      "name": "Empty"
    },
    {
      "x": -4,
      "y": -4,
      "z": 4,
      "name": "Wood_Poisoned_Trunk"
    },
    {
      "x": -4,
      "y": -3,
      "z": 4,
      "name": "Wood_Poisoned_Trunk"
    },
    {
      "x": -4,
      "y": -2,
      "z": 4,
      "name": "Wood_Poisoned_Trunk"
    },
    {
      "x": -4,
      "y": -1,
      "z": 4,
      "name": "Wood_Poisoned_Trunk_Full"
    },
    {
      "x": -4,
      "y": 24,
      "z": 4,
      "name": "Empty"
    },
    {
      "x": -4,
      "y": -2,
      "z": 5,
      "name": "Wood_Poisoned_Trunk_Full"
    },
    {
      "x": -3,
      "y": -3,
      "z": -6,
      "name": "Wood_Poisoned_Trunk"
    },
    {
      "x": -3,
      "y": -2,
      "z": -6,
      "name": "Wood_Poisoned_Trunk"
    },
    {
      "x": -3,
      "y": -1,
      "z": -6,
      "name": "Wood_Poisoned_Trunk_Full"
    },
    {
      "x": -3,
      "y": -2,
      "z": -5,
      "name": "Wood_Poisoned_Trunk"
    },
    {
      "x": -3,
      "y": -1,
      "z": -5,
      "name": "Wood_Poisoned_Trunk_Full"
    },
    {
      "x": -3,
      "y": 20,
      "z": -5,
      "name": "Empty"
    },
    {
      "x": -3,
      "y": 21,
      "z": -5,
      "name": "Empty"
    },
    {
      "x": -3,
      "y": -1,
      "z": -4,
      "name": "Wood_Poisoned_Trunk"
    },
    {
      "x": -3,
      "y": 0,
      "z": -4,
      "name": "Wood_Poisoned_Trunk_Full"
    },
    {
      "x": -3,
      "y": 19,
      "z": -4,
      "name": "Empty"
    },
    {
      "x": -3,
      "y": 20,
      "z": -4,
      "name": "Empty"
    },
    {
      "x": -3,
      "y": 21,
      "z": -4,
      "name": "Empty"
    },
    {
      "x": -3,
      "y": 22,
      "z": -4,
      "name": "Empty"
    },
    {
      "x": -3,
      "y": 24,
      "z": -4,
      "name": "Empty"
    },
    {
      "x": -3,
      "y": 35,
      "z": -4,
      "name": "Empty"
    },
    {
      "x": -3,
      "y": 18,
      "z": -3,
      "name": "Empty"
    },
    {
      "x": -3,
      "y": 20,
      "z": -3,
      "name": "Empty"
    },
    {
      "x": -3,
      "y": 21,
      "z": -3,
      "name": "Empty"
    },
    {
      "x": -3,
      "y": 22,
      "z": -3,
      "name": "Empty"
    },
    {
      "x": -3,
      "y": 24,
      "z": -3,
      "name": "Empty"
    },
    {
      "x": -3,
      "y": 25,
      "z": -3,
      "name": "Empty"
    },
    {
      "x": -3,
      "y": 35,
      "z": -3,
      "name": "Empty"
    },
    {
      "x": -3,
      "y": 1,
      "z": -2,
      "name": "Wood_Poisoned_Trunk"
    },
    {
      "x": -3,
      "y": 2,
      "z": -2,
      "name": "Wood_Poisoned_Trunk"
    },
    {
      "x": -3,
      "y": 3,
      "z": -2,
      "name": "Wood_Poisoned_Trunk_Full"
    },
    {
      "x": -3,
      "y": 9,
      "z": -2,
      "name": "Plant_Vine_Wall_Poisoned",
      "rotation": 3
    },
    {
      "x": -3,
      "y": 10,
      "z": -2,
      "name": "Wood_Crystal_Branch_Short",
      "rotation": 3
    },
    {
      "x": -3,
      "y": 12,
      "z": -2,
      "name": "Wood_Crystal_Branch_Short",
      "rotation": 3
    },
    {
      "x": -3,
      "y": 13,
      "z": -2,
      "name": "Wood_Crystal_Branch_Short",
      "rotation": 3
    },
    {
      "x": -3,
      "y": 17,
      "z": -2,
      "name": "Empty"
    },
    {
      "x": -3,
      "y": 18,
      "z": -2,
      "name": "Empty"
    },
    {
      "x": -3,
      "y": 19,
      "z": -2,
      "name": "Empty"
    },
    {
      "x": -3,
      "y": 20,
      "z": -2,
      "name": "Empty"
    },
    {
      "x": -3,
      "y": 21,
      "z": -2,
      "name": "Empty"
    },
    {
      "x": -3,
      "y": 22,
      "z": -2,
      "name": "Empty"
    },
    {
      "x": -3,
      "y": 25,
      "z": -2,
      "name": "Empty"
    },
    {
      "x": -3,
      "y": 28,
      "z": -2,
      "name": "Empty",
      "rotation": 8
    },
    {
      "x": -3,
      "y": 29,
      "z": -2,
      "name": "Empty"
    },
    {
      "x": -3,
      "y": 32,
      "z": -2,
      "name": "Empty"
    },
    {
      "x": -3,
      "y": 35,
      "z": -2,
      "name": "Empty"
    },
    {
      "x": -3,
      "y": 36,
      "z": -2,
      "name": "Empty"
    },
    {
      "x": -3,
      "y": 37,
      "z": -2,
      "name": "Empty"
    },
    {
      "x": -3,
      "y": 42,
      "z": -2,
      "name": "Empty"
    },
    {
      "x": -3,
      "y": 46,
      "z": -2,
      "name": "Empty"
    },
    {
      "x": -3,
      "y": 3,
      "z": -1,
      "name": "Wood_Poisoned_Trunk"
    },
    {
      "x": -3,
      "y": 4,
      "z": -1,
      "name": "Wood_Poisoned_Trunk"
    },
    {
      "x": -3,
      "y": 5,
      "z": -1,
      "name": "Wood_Poisoned_Trunk_Full"
    },
    {
      "x": -3,
      "y": 6,
      "z": -1,
      "name": "Plant_Vine_Wall_Poisoned",
      "rotation": 3
    },
    {
      "x": -3,
      "y": 8,
      "z": -1,
      "name": "Plant_Vine_Wall_Poisoned",
      "rotation": 3
    },
    {
      "x": -3,
      "y": 9,
      "z": -1,
      "name": "Plant_Vine_Wall_Poisoned",
      "rotation": 3
    },
    {
      "x": -3,
      "y": 10,
      "z": -1,
      "name": "Plant_Vine_Wall_Poisoned",
      "rotation": 3
    },
    {
      "x": -3,
      "y": 11,
      "z": -1,
      "name": "Plant_Vine_Wall_Poisoned",
      "rotation": 3
    },
    {
      "x": -3,
      "y": 13,
      "z": -1,
      "name": "Wood_Crystal_Branch_Short",
      "rotation": 3
    },
    {
      "x": -3,
      "y": 14,
      "z": -1,
      "name": "Wood_Crystal_Branch_Corner",
      "rotation": 3
    },
    {
      "x": -3,
      "y": 16,
      "z": -1,
      "name": "Empty"
    },
    {
      "x": -3,
      "y": 17,
      "z": -1,
      "name": "Empty"
    },
    {
      "x": -3,
      "y": 18,
      "z": -1,
      "name": "Wood_Poisoned_Trunk_Full"
    },
    {
      "x": -3,
      "y": 19,
      "z": -1,
      "name": "Empty"
    },
    {
      "x": -3,
      "y": 21,
      "z": -1,
      "name": "Empty"
    },
    {
      "x": -3,
      "y": 22,
      "z": -1,
      "name": "Wood_Poisoned_Trunk_Full"
    },
    {
      "x": -3,
      "y": 24,
      "z": -1,
      "name": "Empty"
    },
    {
      "x": -3,
      "y": 25,
      "z": -1,
      "name": "Wood_Poisoned_Trunk_Full"
    },
    {
      "x": -3,
      "y": 26,
      "z": -1,
      "name": "Empty"
    },
    {
      "x": -3,
      "y": 28,
      "z": -1,
      "name": "Empty"
    },
    {
      "x": -3,
      "y": 29,
      "z": -1,
      "name": "Wood_Poisoned_Trunk_Full"
    },
    {
      "x": -3,
      "y": 30,
      "z": -1,
      "name": "Empty"
    },
    {
      "x": -3,
      "y": 31,
      "z": -1,
      "name": "Empty"
    },
    {
      "x": -3,
      "y": 32,
      "z": -1,
      "name": "Wood_Poisoned_Trunk_Full"
    },
    {
      "x": -3,
      "y": 33,
      "z": -1,
      "name": "Empty"
    },
    {
      "x": -3,
      "y": 35,
      "z": -1,
      "name": "Empty"
    },
    {
      "x": -3,
      "y": 37,
      "z": -1,
      "name": "Wood_Poisoned_Trunk_Full"
    },
    {
      "x": -3,
      "y": 38,
      "z": -1,
      "name": "Empty"
    },
    {
      "x": -3,
      "y": 42,
      "z": -1,
      "name": "Wood_Poisoned_Trunk_Full"
    },
    {
      "x": -3,
      "y": 43,
      "z": -1,
      "name": "Empty"
    },
    {
      "x": -3,
      "y": 45,
      "z": -1,
      "name": "Empty",
      "rotation": 8
    },
    {
      "x": -3,
      "y": 46,
      "z": -1,
      "name": "Wood_Poisoned_Trunk_Full"
    },
    {
      "x": -3,
      "y": 47,
      "z": -1,
      "name": "Empty"
    },
    {
      "x": -3,
      "y": 2,
      "z": 0,
      "name": "Wood_Poisoned_Trunk"
    },
    {
      "x": -3,
      "y": 3,
      "z": 0,
      "name": "Wood_Poisoned_Trunk"
    },
    {
      "x": -3,
      "y": 4,
      "z": 0,
      "name": "Wood_Poisoned_Trunk"
    },
    {
      "x": -3,
      "y": 5,
      "z": 0,
      "name": "Wood_Poisoned_Trunk"
    },
    {
      "x": -3,
      "y": 6,
      "z": 0,
      "name": "Wood_Poisoned_Trunk"
    },
    {
      "x": -3,
      "y": 7,
      "z": 0,
      "name": "Wood_Poisoned_Trunk"
    },
    {
      "x": -3,
      "y": 8,
      "z": 0,
      "name": "Wood_Poisoned_Trunk_Full"
    },
    {
      "x": -3,
      "y": 11,
      "z": 0,
      "name": "Plant_Vine_Wall_Poisoned",
      "rotation": 3
    },
    {
      "x": -3,
      "y": 12,
      "z": 0,
      "name": "Plant_Vine_Wall_Poisoned",
      "rotation": 3
    },
    {
      "x": -3,
      "y": 14,
      "z": 0,
      "name": "Plant_Vine_Wall_Poisoned",
      "rotation": 3
    },
    {
      "x": -3,
      "y": 17,
      "z": 0,
      "name": "Empty"
    },
    {
      "x": -3,
      "y": 18,
      "z": 0,
      "name": "Empty"
    },
    {
      "x": -3,
      "y": 19,
      "z": 0,
      "name": "Empty"
    },
    {
      "x": -3,
      "y": 22,
      "z": 0,
      "name": "Empty"
    },
    {
      "x": -3,
      "y": 24,
      "z": 0,
      "name": "Empty"
    },
    {
      "x": -3,
      "y": 25,
      "z": 0,
      "name": "Empty"
    },
    {
      "x": -3,
      "y": 29,
      "z": 0,
      "name": "Empty"
    },
    {
      "x": -3,
      "y": 31,
      "z": 0,
      "name": "Empty"
    },
    {
      "x": -3,
      "y": 32,
      "z": 0,
      "name": "Empty"
    },
    {
      "x": -3,
      "y": 37,
      "z": 0,
      "name": "Empty"
    },
    {
      "x": -3,
      "y": 41,
      "z": 0,
      "name": "Empty"
    },
    {
      "x": -3,
      "y": 42,
      "z": 0,
      "name": "Empty"
    },
    {
      "x": -3,
      "y": 46,
      "z": 0,
      "name": "Empty"
    },
    {
      "x": -3,
      "y": 1,
      "z": 1,
      "name": "Wood_Poisoned_Trunk"
    },
    {
      "x": -3,
      "y": 2,
      "z": 1,
      "name": "Wood_Poisoned_Trunk"
    },
    {
      "x": -3,
      "y": 3,
      "z": 1,
      "name": "Wood_Poisoned_Trunk_Full"
    },
    {
      "x": -3,
      "y": 7,
      "z": 1,
      "name": "Wood_Crystal_Branch_Short"
    },
    {
      "x": -3,
      "y": 8,
      "z": 1,
      "name": "Wood_Crystal_Branch_Short",
      "rotation": 3
    },
    {
      "x": -3,
      "y": 9,
      "z": 1,
      "name": "Wood_Crystal_Branch_Short",
      "rotation": 3
    },
    {
      "x": -3,
      "y": 18,
      "z": 1,
      "name": "Empty"
    },
    {
      "x": -3,
      "y": 19,
      "z": 1,
      "name": "Empty"
    },
    {
      "x": -3,
      "y": 21,
      "z": 1,
      "name": "Empty"
    },
    {
      "x": -3,
      "y": 22,
      "z": 1,
      "name": "Empty"
    },
    {
      "x": -3,
      "y": 24,
      "z": 1,
      "name": "Empty"
    },
    {
      "x": -3,
      "y": 25,
      "z": 1,
      "name": "Empty"
    },
    {
      "x": -3,
      "y": 28,
      "z": 1,
      "name": "Empty"
    },
    {
      "x": -3,
      "y": 30,
      "z": 1,
      "name": "Empty"
    },
    {
      "x": -3,
      "y": 31,
      "z": 1,
      "name": "Empty"
    },
    {
      "x": -3,
      "y": 41,
      "z": 1,
      "name": "Empty"
    },
    {
      "x": -3,
      "y": -1,
      "z": 2,
      "name": "Wood_Poisoned_Trunk"
    },
    {
      "x": -3,
      "y": 0,
      "z": 2,
      "name": "Wood_Poisoned_Trunk"
    },
    {
      "x": -3,
      "y": 1,
      "z": 2,
      "name": "Wood_Poisoned_Trunk"
    },
    {
      "x": -3,
      "y": 2,
      "z": 2,
      "name": "Wood_Poisoned_Trunk_Full"
    },
    {
      "x": -3,
      "y": 18,
      "z": 2,
      "name": "Empty"
    },
    {
      "x": -3,
      "y": 21,
      "z": 2,
      "name": "Empty"
    },
    {
      "x": -3,
      "y": 22,
      "z": 2,
      "name": "Empty"
    },
    {
      "x": -3,
      "y": 24,
      "z": 2,
      "name": "Empty"
    },
    {
      "x": -3,
      "y": 25,
      "z": 2,
      "name": "Empty"
    },
    {
      "x": -3,
      "y": 28,
      "z": 2,
      "name": "Empty"
    },
    {
      "x": -3,
      "y": 31,
      "z": 2,
      "name": "Empty"
    },
    {
      "x": -3,
      "y": -2,
      "z": 3,
      "name": "Wood_Poisoned_Trunk"
    },
    {
      "x": -3,
      "y": -1,
      "z": 3,
      "name": "Wood_Poisoned_Trunk"
    },
    {
      "x": -3,
      "y": 0,
      "z": 3,
      "name": "Wood_Poisoned_Trunk_Full"
    },
    {
      "x": -3,
      "y": 21,
      "z": 3,
      "name": "Empty"
    },
    {
      "x": -3,
      "y": 22,
      "z": 3,
      "name": "Empty"
    },
    {
      "x": -3,
      "y": 24,
      "z": 3,
      "name": "Empty"
    },
    {
      "x": -3,
      "y": 28,
      "z": 3,
      "name": "Empty"
    },
    {
      "x": -3,
      "y": -2,
      "z": 4,
      "name": "Wood_Poisoned_Trunk"
    },
    {
      "x": -3,
      "y": -1,
      "z": 4,
      "name": "Wood_Poisoned_Trunk_Full"
    },
    {
      "x": -3,
      "y": 22,
      "z": 4,
      "name": "Empty"
    },
    {
      "x": -3,
      "y": 22,
      "z": 5,
      "name": "Empty"
    },
    {
      "x": -2,
      "y": 21,
      "z": -11,
      "name": "Empty"
    },
    {
      "x": -2,
      "y": 20,
      "z": -10,
      "name": "Empty"
    },
    {
      "x": -2,
      "y": 21,
      "z": -10,
      "name": "Empty"
    },
    {
      "x": -2,
      "y": 20,
      "z": -9,
      "name": "Empty"
    },
    {
      "x": -2,
      "y": 21,
      "z": -9,
      "name": "Empty"
    },
    {
      "x": -2,
      "y": 20,
      "z": -8,
      "name": "Empty"
    },
    {
      "x": -2,
      "y": 21,
      "z": -8,
      "name": "Empty"
    },
    {
      "x": -2,
      "y": 20,
      "z": -7,
      "name": "Empty"
    },
    {
      "x": -2,
      "y": -2,
      "z": -6,
      "name": "Wood_Poisoned_Trunk"
    },
    {
      "x": -2,
      "y": -1,
      "z": -6,
      "name": "Wood_Poisoned_Trunk"
    },
    {
      "x": -2,
      "y": 0,
      "z": -6,
      "name": "Wood_Poisoned_Trunk_Full"
    },
    {
      "x": -2,
      "y": 19,
      "z": -6,
      "name": "Empty"
    },
    {
      "x": -2,
      "y": 20,
      "z": -6,
      "name": "Empty"
    },
    {
      "x": -2,
      "y": 24,
      "z": -6,
      "name": "Empty"
    },
    {
      "x": -2,
      "y": 28,
      "z": -6,
      "name": "Empty"
    },
    {
      "x": -2,
      "y": -2,
      "z": -5,
      "name": "Wood_Poisoned_Trunk"
    },
    {
      "x": -2,
      "y": -1,
      "z": -5,
      "name": "Wood_Poisoned_Trunk"
    },
    {
      "x": -2,
      "y": 0,
      "z": -5,
      "name": "Wood_Poisoned_Trunk"
    },
    {
      "x": -2,
      "y": 1,
      "z": -5,
      "name": "Wood_Poisoned_Trunk"
    },
    {
      "x": -2,
      "y": 2,
      "z": -5,
      "name": "Wood_Poisoned_Trunk"
    },
    {
      "x": -2,
      "y": 3,
      "z": -5,
      "name": "Wood_Poisoned_Trunk_Full"
    },
    {
      "x": -2,
      "y": 19,
      "z": -5,
      "name": "Empty"
    },
    {
      "x": -2,
      "y": 20,
      "z": -5,
      "name": "Empty"
    },
    {
      "x": -2,
      "y": 24,
      "z": -5,
      "name": "Empty"
    },
    {
      "x": -2,
      "y": 28,
      "z": -5,
      "name": "Empty"
    },
    {
      "x": -2,
      "y": 33,
      "z": -5,
      "name": "Empty"
    },
    {
      "x": -2,
      "y": 0,
      "z": -4,
      "name": "Wood_Poisoned_Trunk"
    },
    {
      "x": -2,
      "y": 1,
      "z": -4,
      "name": "Wood_Poisoned_Trunk"
    },
    {
      "x": -2,
      "y": 2,
      "z": -4,
      "name": "Wood_Poisoned_Trunk"
    },
    {
      "x": -2,
      "y": 3,
      "z": -4,
      "name": "Wood_Poisoned_Trunk"
    },
    {
      "x": -2,
      "y": 4,
      "z": -4,
      "name": "Wood_Poisoned_Trunk_Full"
    },
    {
      "x": -2,
      "y": 19,
      "z": -4,
      "name": "Empty"
    },
    {
      "x": -2,
      "y": 20,
      "z": -4,
      "name": "Empty"
    },
    {
      "x": -2,
      "y": 21,
      "z": -4,
      "name": "Empty"
    },
    {
      "x": -2,
      "y": 24,
      "z": -4,
      "name": "Empty"
    },
    {
      "x": -2,
      "y": 28,
      "z": -4,
      "name": "Empty"
    },
    {
      "x": -2,
      "y": 33,
      "z": -4,
      "name": "Empty"
    },
    {
      "x": -2,
      "y": 35,
      "z": -4,
      "name": "Empty"
    },
    {
      "x": -2,
      "y": 44,
      "z": -4,
      "name": "Empty"
    },
    {
      "x": -2,
      "y": 3,
      "z": -3,
      "name": "Wood_Poisoned_Trunk"
    },
    {
      "x": -2,
      "y": 4,
      "z": -3,
      "name": "Wood_Poisoned_Trunk"
    },
    {
      "x": -2,
      "y": 5,
      "z": -3,
      "name": "Wood_Poisoned_Trunk_Full"
    },
    {
      "x": -2,
      "y": 8,
      "z": -3,
      "name": "Wood_Crystal_Branch_Short",
      "rotation": 3
    },
    {
      "x": -2,
      "y": 9,
      "z": -3,
      "name": "Wood_Crystal_Branch_Short",
      "rotation": 3
    },
    {
      "x": -2,
      "y": 10,
      "z": -3,
      "name": "Plant_Vine_Wall_Poisoned",
      "rotation": 2
    },
    {
      "x": -2,
      "y": 11,
      "z": -3,
      "name": "Plant_Vine_Wall_Poisoned",
      "rotation": 2
    },
    {
      "x": -2,
      "y": 12,
      "z": -3,
      "name": "Plant_Vine_Wall_Poisoned",
      "rotation": 2
    },
    {
      "x": -2,
      "y": 15,
      "z": -3,
      "name": "Wood_Crystal_Branch_Short",
      "rotation": 2
    },
    {
      "x": -2,
      "y": 16,
      "z": -3,
      "name": "Wood_Crystal_Branch_Short",
      "rotation": 2
    },
    {
      "x": -2,
      "y": 17,
      "z": -3,
      "name": "Empty"
    },
    {
      "x": -2,
      "y": 19,
      "z": -3,
      "name": "Empty"
    },
    {
      "x": -2,
      "y": 20,
      "z": -3,
      "name": "Empty"
    },
    {
      "x": -2,
      "y": 21,
      "z": -3,
      "name": "Empty"
    },
    {
      "x": -2,
      "y": 22,
      "z": -3,
      "name": "Empty"
    },
    {
      "x": -2,
      "y": 24,
      "z": -3,
      "name": "Empty"
    },
    {
      "x": -2,
      "y": 28,
      "z": -3,
      "name": "Empty"
    },
    {
      "x": -2,
      "y": 33,
      "z": -3,
      "name": "Empty"
    },
    {
      "x": -2,
      "y": 35,
      "z": -3,
      "name": "Empty"
    },
    {
      "x": -2,
      "y": 36,
      "z": -3,
      "name": "Empty"
    },
    {
      "x": -2,
      "y": 37,
      "z": -3,
      "name": "Empty"
    },
    {
      "x": -2,
      "y": 40,
      "z": -3,
      "name": "Empty"
    },
    {
      "x": -2,
      "y": 44,
      "z": -3,
      "name": "Empty"
    },
    {
      "x": -2,
      "y": 46,
      "z": -3,
      "name": "Empty"
    },
    {
      "x": -2,
      "y": 48,
      "z": -3,
      "name": "Empty"
    },
    {
      "x": -2,
      "y": 1,
      "z": -2,
      "name": "Wood_Poisoned_Trunk"
    },
    {
      "x": -2,
      "y": 2,
      "z": -2,
      "name": "Wood_Poisoned_Trunk"
    },
    {
      "x": -2,
      "y": 3,
      "z": -2,
      "name": "Wood_Poisoned_Trunk"
    },
    {
      "x": -2,
      "y": 4,
      "z": -2,
      "name": "Wood_Poisoned_Trunk"
    },
    {
      "x": -2,
      "y": 5,
      "z": -2,
      "name": "Wood_Poisoned_Trunk"
    },
    {
      "x": -2,
      "y": 6,
      "z": -2,
      "name": "Wood_Poisoned_Trunk"
    },
    {
      "x": -2,
      "y": 7,
      "z": -2,
      "name": "Wood_Poisoned_Trunk"
    },
    {
      "x": -2,
      "y": 8,
      "z": -2,
      "name": "Wood_Poisoned_Trunk"
    },
    {
      "x": -2,
      "y": 9,
      "z": -2,
      "name": "Wood_Poisoned_Trunk"
    },
    {
      "x": -2,
      "y": 10,
      "z": -2,
      "name": "Wood_Poisoned_Trunk"
    },
    {
      "x": -2,
      "y": 11,
      "z": -2,
      "name": "Wood_Poisoned_Trunk"
    },
    {
      "x": -2,
      "y": 12,
      "z": -2,
      "name": "Wood_Poisoned_Trunk"
    },
    {
      "x": -2,
      "y": 13,
      "z": -2,
      "name": "Wood_Poisoned_Trunk"
    },
    {
      "x": -2,
      "y": 14,
      "z": -2,
      "name": "Wood_Poisoned_Trunk"
    },
    {
      "x": -2,
      "y": 15,
      "z": -2,
      "name": "Wood_Poisoned_Trunk"
    },
    {
      "x": -2,
      "y": 16,
      "z": -2,
      "name": "Wood_Poisoned_Trunk"
    },
    {
      "x": -2,
      "y": 17,
      "z": -2,
      "name": "Wood_Poisoned_Trunk"
    },
    {
      "x": -2,
      "y": 18,
      "z": -2,
      "name": "Wood_Poisoned_Trunk"
    },
    {
      "x": -2,
      "y": 19,
      "z": -2,
      "name": "Wood_Poisoned_Trunk"
    },
    {
      "x": -2,
      "y": 20,
      "z": -2,
      "name": "Wood_Poisoned_Trunk"
    },
    {
      "x": -2,
      "y": 21,
      "z": -2,
      "name": "Wood_Poisoned_Trunk"
    },
    {
      "x": -2,
      "y": 22,
      "z": -2,
      "name": "Wood_Poisoned_Trunk"
    },
    {
      "x": -2,
      "y": 23,
      "z": -2,
      "name": "Wood_Poisoned_Trunk"
    },
    {
      "x": -2,
      "y": 24,
      "z": -2,
      "name": "Wood_Poisoned_Trunk"
    },
    {
      "x": -2,
      "y": 25,
      "z": -2,
      "name": "Wood_Poisoned_Trunk"
    },
    {
      "x": -2,
      "y": 26,
      "z": -2,
      "name": "Wood_Poisoned_Trunk_Full"
    },
    {
      "x": -2,
      "y": 28,
      "z": -2,
      "name": "Empty"
    },
    {
      "x": -2,
      "y": 29,
      "z": -2,
      "name": "Empty"
    },
    {
      "x": -2,
      "y": 31,
      "z": -2,
      "name": "Empty"
    },
    {
      "x": -2,
      "y": 32,
      "z": -2,
      "name": "Empty"
    },
    {
      "x": -2,
      "y": 33,
      "z": -2,
      "name": "Empty"
    },
    {
      "x": -2,
      "y": 34,
      "z": -2,
      "name": "Empty"
    },
    {
      "x": -2,
      "y": 35,
      "z": -2,
      "name": "Empty"
    },
    {
      "x": -2,
      "y": 36,
      "z": -2,
      "name": "Empty"
    },
    {
      "x": -2,
      "y": 37,
      "z": -2,
      "name": "Empty"
    },
    {
      "x": -2,
      "y": 40,
      "z": -2,
      "name": "Empty"
    },
    {
      "x": -2,
      "y": 42,
      "z": -2,
      "name": "Empty"
    },
    {
      "x": -2,
      "y": 44,
      "z": -2,
      "name": "Empty"
    },
    {
      "x": -2,
      "y": 46,
      "z": -2,
      "name": "Empty"
    },
    {
      "x": -2,
      "y": 47,
      "z": -2,
      "name": "Empty"
    },
    {
      "x": -2,
      "y": 48,
      "z": -2,
      "name": "Empty"
    },
    {
      "x": -2,
      "y": 49,
      "z": -2,
      "name": "Empty"
    },
    {
      "x": -2,
      "y": 50,
      "z": -2,
      "name": "Empty"
    },
    {
      "x": -2,
      "y": 51,
      "z": -2,
      "name": "Empty"
    },
    {
      "x": -2,
      "y": -4,
      "z": -1,
      "name": "Wood_Poisoned_Trunk"
    },
    {
      "x": -2,
      "y": -3,
      "z": -1,
      "name": "Wood_Poisoned_Trunk"
    },
    {
      "x": -2,
      "y": -2,
      "z": -1,
      "name": "Wood_Poisoned_Trunk"
    },
    {
      "x": -2,
      "y": -1,
      "z": -1,
      "name": "Wood_Poisoned_Trunk_Full"
    },
    {
      "x": -2,
      "y": 2,
      "z": -1,
      "name": "Wood_Poisoned_Trunk"
    },
    {
      "x": -2,
      "y": 3,
      "z": -1,
      "name": "Wood_Poisoned_Trunk"
    },
    {
      "x": -2,
      "y": 4,
      "z": -1,
      "name": "Wood_Poisoned_Trunk"
    },
    {
      "x": -2,
      "y": 5,
      "z": -1,
      "name": "Wood_Poisoned_Trunk"
    },
    {
      "x": -2,
      "y": 6,
      "z": -1,
      "name": "Wood_Poisoned_Trunk"
    },
    {
      "x": -2,
      "y": 7,
      "z": -1,
      "name": "Wood_Poisoned_Trunk"
    },
    {
      "x": -2,
      "y": 8,
      "z": -1,
      "name": "Wood_Poisoned_Trunk"
    },
    {
      "x": -2,
      "y": 9,
      "z": -1,
      "name": "Wood_Poisoned_Trunk"
    },
    {
      "x": -2,
      "y": 10,
      "z": -1,
      "name": "Wood_Poisoned_Trunk"
    },
    {
      "x": -2,
      "y": 11,
      "z": -1,
      "name": "Wood_Poisoned_Trunk"
    },
    {
      "x": -2,
      "y": 12,
      "z": -1,
      "name": "Wood_Poisoned_Trunk"
    },
    {
      "x": -2,
      "y": 13,
      "z": -1,
      "name": "Wood_Poisoned_Trunk"
    },
    {
      "x": -2,
      "y": 14,
      "z": -1,
      "name": "Wood_Poisoned_Trunk"
    },
    {
      "x": -2,
      "y": 15,
      "z": -1,
      "name": "Wood_Poisoned_Trunk"
    },
    {
      "x": -2,
      "y": 16,
      "z": -1,
      "name": "Wood_Poisoned_Trunk"
    },
    {
      "x": -2,
      "y": 17,
      "z": -1,
      "name": "Wood_Poisoned_Trunk"
    },
    {
      "x": -2,
      "y": 18,
      "z": -1,
      "name": "Wood_Poisoned_Trunk"
    },
    {
      "x": -2,
      "y": 19,
      "z": -1,
      "name": "Wood_Poisoned_Trunk"
    },
    {
      "x": -2,
      "y": 20,
      "z": -1,
      "name": "Wood_Poisoned_Trunk"
    },
    {
      "x": -2,
      "y": 21,
      "z": -1,
      "name": "Wood_Poisoned_Trunk"
    },
    {
      "x": -2,
      "y": 22,
      "z": -1,
      "name": "Wood_Poisoned_Trunk"
    },
    {
      "x": -2,
      "y": 23,
      "z": -1,
      "name": "Wood_Poisoned_Trunk"
    },
    {
      "x": -2,
      "y": 24,
      "z": -1,
      "name": "Wood_Poisoned_Trunk"
    },
    {
      "x": -2,
      "y": 25,
      "z": -1,
      "name": "Wood_Poisoned_Trunk"
    },
    {
      "x": -2,
      "y": 26,
      "z": -1,
      "name": "Wood_Poisoned_Trunk"
    },
    {
      "x": -2,
      "y": 27,
      "z": -1,
      "name": "Wood_Poisoned_Trunk"
    },
    {
      "x": -2,
      "y": 28,
      "z": -1,
      "name": "Wood_Poisoned_Trunk"
    },
    {
      "x": -2,
      "y": 29,
      "z": -1,
      "name": "Wood_Poisoned_Trunk"
    },
    {
      "x": -2,
      "y": 30,
      "z": -1,
      "name": "Wood_Poisoned_Trunk"
    },
    {
      "x": -2,
      "y": 31,
      "z": -1,
      "name": "Wood_Poisoned_Trunk"
    },
    {
      "x": -2,
      "y": 32,
      "z": -1,
      "name": "Wood_Poisoned_Trunk"
    },
    {
      "x": -2,
      "y": 33,
      "z": -1,
      "name": "Wood_Poisoned_Trunk"
    },
    {
      "x": -2,
      "y": 34,
      "z": -1,
      "name": "Wood_Poisoned_Trunk"
    },
    {
      "x": -2,
      "y": 35,
      "z": -1,
      "name": "Wood_Poisoned_Trunk"
    },
    {
      "x": -2,
      "y": 36,
      "z": -1,
      "name": "Wood_Poisoned_Trunk"
    },
    {
      "x": -2,
      "y": 37,
      "z": -1,
      "name": "Wood_Poisoned_Trunk"
    },
    {
      "x": -2,
      "y": 38,
      "z": -1,
      "name": "Wood_Poisoned_Trunk"
    },
    {
      "x": -2,
      "y": 39,
      "z": -1,
      "name": "Wood_Poisoned_Trunk"
    },
    {
      "x": -2,
      "y": 40,
      "z": -1,
      "name": "Wood_Poisoned_Trunk"
    },
    {
      "x": -2,
      "y": 41,
      "z": -1,
      "name": "Wood_Poisoned_Trunk"
    },
    {
      "x": -2,
      "y": 42,
      "z": -1,
      "name": "Wood_Poisoned_Trunk"
    },
    {
      "x": -2,
      "y": 43,
      "z": -1,
      "name": "Wood_Poisoned_Trunk"
    },
    {
      "x": -2,
      "y": 44,
      "z": -1,
      "name": "Wood_Poisoned_Trunk"
    },
    {
      "x": -2,
      "y": 45,
      "z": -1,
      "name": "Wood_Poisoned_Trunk"
    },
    {
      "x": -2,
      "y": 46,
      "z": -1,
      "name": "Wood_Poisoned_Trunk"
    },
    {
      "x": -2,
      "y": 47,
      "z": -1,
      "name": "Wood_Poisoned_Trunk_Full"
    },
    {
      "x": -2,
      "y": 48,
      "z": -1,
      "name": "Empty"
    },
    {
      "x": -2,
      "y": 49,
      "z": -1,
      "name": "Empty"
    },
    {
      "x": -2,
      "y": 50,
      "z": -1,
      "name": "Empty"
    },
    {
      "x": -2,
      "y": -1,
      "z": 0,
      "name": "Wood_Poisoned_Trunk"
    },
    {
      "x": -2,
      "y": 0,
      "z": 0,
      "name": "Wood_Poisoned_Trunk"
    },
    {
      "x": -2,
      "y": 1,
      "z": 0,
      "name": "Wood_Poisoned_Trunk"
    },
    {
      "x": -2,
      "y": 2,
      "z": 0,
      "name": "Wood_Poisoned_Trunk"
    },
    {
      "x": -2,
      "y": 3,
      "z": 0,
      "name": "Wood_Poisoned_Trunk"
    },
    {
      "x": -2,
      "y": 4,
      "z": 0,
      "name": "Wood_Poisoned_Trunk"
    },
    {
      "x": -2,
      "y": 5,
      "z": 0,
      "name": "Wood_Poisoned_Trunk"
    },
    {
      "x": -2,
      "y": 6,
      "z": 0,
      "name": "Wood_Poisoned_Trunk"
    },
    {
      "x": -2,
      "y": 7,
      "z": 0,
      "name": "Wood_Poisoned_Trunk"
    },
    {
      "x": -2,
      "y": 8,
      "z": 0,
      "name": "Wood_Poisoned_Trunk"
    },
    {
      "x": -2,
      "y": 9,
      "z": 0,
      "name": "Wood_Poisoned_Trunk"
    },
    {
      "x": -2,
      "y": 10,
      "z": 0,
      "name": "Wood_Poisoned_Trunk"
    },
    {
      "x": -2,
      "y": 11,
      "z": 0,
      "name": "Wood_Poisoned_Trunk"
    },
    {
      "x": -2,
      "y": 12,
      "z": 0,
      "name": "Wood_Poisoned_Trunk"
    },
    {
      "x": -2,
      "y": 13,
      "z": 0,
      "name": "Wood_Poisoned_Trunk"
    },
    {
      "x": -2,
      "y": 14,
      "z": 0,
      "name": "Wood_Poisoned_Trunk"
    },
    {
      "x": -2,
      "y": 15,
      "z": 0,
      "name": "Wood_Poisoned_Trunk"
    },
    {
      "x": -2,
      "y": 16,
      "z": 0,
      "name": "Wood_Poisoned_Trunk"
    },
    {
      "x": -2,
      "y": 17,
      "z": 0,
      "name": "Wood_Poisoned_Trunk"
    },
    {
      "x": -2,
      "y": 18,
      "z": 0,
      "name": "Wood_Poisoned_Trunk"
    },
    {
      "x": -2,
      "y": 19,
      "z": 0,
      "name": "Wood_Poisoned_Trunk"
    },
    {
      "x": -2,
      "y": 20,
      "z": 0,
      "name": "Wood_Poisoned_Trunk"
    },
    {
      "x": -2,
      "y": 21,
      "z": 0,
      "name": "Wood_Poisoned_Trunk"
    },
    {
      "x": -2,
      "y": 22,
      "z": 0,
      "name": "Wood_Poisoned_Trunk"
    },
    {
      "x": -2,
      "y": 23,
      "z": 0,
      "name": "Wood_Poisoned_Trunk"
    },
    {
      "x": -2,
      "y": 24,
      "z": 0,
      "name": "Wood_Poisoned_Trunk"
    },
    {
      "x": -2,
      "y": 25,
      "z": 0,
      "name": "Wood_Poisoned_Trunk"
    },
    {
      "x": -2,
      "y": 26,
      "z": 0,
      "name": "Wood_Poisoned_Trunk"
    },
    {
      "x": -2,
      "y": 27,
      "z": 0,
      "name": "Wood_Poisoned_Trunk"
    },
    {
      "x": -2,
      "y": 28,
      "z": 0,
      "name": "Wood_Poisoned_Trunk"
    },
    {
      "x": -2,
      "y": 29,
      "z": 0,
      "name": "Wood_Poisoned_Trunk"
    },
    {
      "x": -2,
      "y": 30,
      "z": 0,
      "name": "Wood_Poisoned_Trunk"
    },
    {
      "x": -2,
      "y": 31,
      "z": 0,
      "name": "Wood_Poisoned_Trunk_Full"
    },
    {
      "x": -2,
      "y": 32,
      "z": 0,
      "name": "Empty"
    },
    {
      "x": -2,
      "y": 34,
      "z": 0,
      "name": "Empty"
    },
    {
      "x": -2,
      "y": 39,
      "z": 0,
      "name": "Empty"
    },
    {
      "x": -2,
      "y": 40,
      "z": 0,
      "name": "Empty"
    },
    {
      "x": -2,
      "y": 41,
      "z": 0,
      "name": "Empty"
    },
    {
      "x": -2,
      "y": 42,
      "z": 0,
      "name": "Empty"
    },
    {
      "x": -2,
      "y": 43,
      "z": 0,
      "name": "Empty"
    },
    {
      "x": -2,
      "y": 44,
      "z": 0,
      "name": "Empty"
    },
    {
      "x": -2,
      "y": 46,
      "z": 0,
      "name": "Empty"
    },
    {
      "x": -2,
      "y": 47,
      "z": 0,
      "name": "Empty"
    },
    {
      "x": -2,
      "y": 48,
      "z": 0,
      "name": "Empty"
    },
    {
      "x": -2,
      "y": 49,
      "z": 0,
      "name": "Empty"
    },
    {
      "x": -2,
      "y": 50,
      "z": 0,
      "name": "Empty"
    },
    {
      "x": -2,
      "y": 1,
      "z": 1,
      "name": "Wood_Poisoned_Trunk"
    },
    {
      "x": -2,
      "y": 2,
      "z": 1,
      "name": "Wood_Poisoned_Trunk"
    },
    {
      "x": -2,
      "y": 3,
      "z": 1,
      "name": "Wood_Poisoned_Trunk"
    },
    {
      "x": -2,
      "y": 4,
      "z": 1,
      "name": "Wood_Poisoned_Trunk"
    },
    {
      "x": -2,
      "y": 5,
      "z": 1,
      "name": "Wood_Poisoned_Trunk"
    },
    {
      "x": -2,
      "y": 6,
      "z": 1,
      "name": "Wood_Poisoned_Trunk"
    },
    {
      "x": -2,
      "y": 7,
      "z": 1,
      "name": "Wood_Poisoned_Trunk"
    },
    {
      "x": -2,
      "y": 8,
      "z": 1,
      "name": "Wood_Poisoned_Trunk"
    },
    {
      "x": -2,
      "y": 9,
      "z": 1,
      "name": "Wood_Poisoned_Trunk"
    },
    {
      "x": -2,
      "y": 10,
      "z": 1,
      "name": "Wood_Poisoned_Trunk"
    },
    {
      "x": -2,
      "y": 11,
      "z": 1,
      "name": "Wood_Poisoned_Trunk_Full"
    },
    {
      "x": -2,
      "y": 12,
      "z": 1,
      "name": "Wood_Crystal_Branch_Short"
    },
    {
      "x": -2,
      "y": 14,
      "z": 1,
      "name": "Plant_Vine_Wall_Poisoned"
    },
    {
      "x": -2,
      "y": 15,
      "z": 1,
      "name": "Plant_Vine_Wall_Poisoned"
    },
    {
      "x": -2,
      "y": 16,
      "z": 1,
      "name": "Plant_Vine_Wall_Poisoned"
    },
    {
      "x": -2,
      "y": 17,
      "z": 1,
      "name": "Empty"
    },
    {
      "x": -2,
      "y": 18,
      "z": 1,
      "name": "Empty"
    },
    {
      "x": -2,
      "y": 20,
      "z": 1,
      "name": "Plant_Vine_Wall_Poisoned"
    },
    {
      "x": -2,
      "y": 21,
      "z": 1,
      "name": "Empty"
    },
    {
      "x": -2,
      "y": 22,
      "z": 1,
      "name": "Empty"
    },
    {
      "x": -2,
      "y": 23,
      "z": 1,
      "name": "Empty"
    },
    {
      "x": -2,
      "y": 24,
      "z": 1,
      "name": "Empty"
    },
    {
      "x": -2,
      "y": 25,
      "z": 1,
      "name": "Empty"
    },
    {
      "x": -2,
      "y": 28,
      "z": 1,
      "name": "Empty"
    },
    {
      "x": -2,
      "y": 31,
      "z": 1,
      "name": "Empty"
    },
    {
      "x": -2,
      "y": 32,
      "z": 1,
      "name": "Empty"
    },
    {
      "x": -2,
      "y": 34,
      "z": 1,
      "name": "Empty"
    },
    {
      "x": -2,
      "y": 39,
      "z": 1,
      "name": "Empty"
    },
    {
      "x": -2,
      "y": 41,
      "z": 1,
      "name": "Empty"
    },
    {
      "x": -2,
      "y": 44,
      "z": 1,
      "name": "Empty"
    },
    {
      "x": -2,
      "y": -1,
      "z": 2,
      "name": "Wood_Poisoned_Trunk"
    },
    {
      "x": -2,
      "y": 0,
      "z": 2,
      "name": "Wood_Poisoned_Trunk"
    },
    {
      "x": -2,
      "y": 1,
      "z": 2,
      "name": "Wood_Poisoned_Trunk"
    },
    {
      "x": -2,
      "y": 2,
      "z": 2,
      "name": "Wood_Poisoned_Trunk"
    },
    {
      "x": -2,
      "y": 3,
      "z": 2,
      "name": "Wood_Poisoned_Trunk"
    },
    {
      "x": -2,
      "y": 4,
      "z": 2,
      "name": "Wood_Poisoned_Trunk"
    },
    {
      "x": -2,
      "y": 5,
      "z": 2,
      "name": "Wood_Poisoned_Trunk_Full"
    },
    {
      "x": -2,
      "y": 6,
      "z": 2,
      "name": "Plant_Vine_Wall_Poisoned"
    },
    {
      "x": -2,
      "y": 7,
      "z": 2,
      "name": "Plant_Vine_Wall_Poisoned"
    },
    {
      "x": -2,
      "y": 8,
      "z": 2,
      "name": "Plant_Vine_Wall_Poisoned"
    },
    {
      "x": -2,
      "y": 9,
      "z": 2,
      "name": "Plant_Vine_Wall_Poisoned"
    },
    {
      "x": -2,
      "y": 10,
      "z": 2,
      "name": "Wood_Crystal_Branch_Corner"
    },
    {
      "x": -2,
      "y": 17,
      "z": 2,
      "name": "Plant_Vine_Wall_Poisoned"
    },
    {
      "x": -2,
      "y": 18,
      "z": 2,
      "name": "Plant_Vine_Wall_Poisoned"
    },
    {
      "x": -2,
      "y": 21,
      "z": 2,
      "name": "Empty"
    },
    {
      "x": -2,
      "y": 22,
      "z": 2,
      "name": "Empty"
    },
    {
      "x": -2,
      "y": 24,
      "z": 2,
      "name": "Empty"
    },
    {
      "x": -2,
      "y": 25,
      "z": 2,
      "name": "Empty"
    },
    {
      "x": -2,
      "y": 28,
      "z": 2,
      "name": "Empty"
    },
    {
      "x": -2,
      "y": 31,
      "z": 2,
      "name": "Empty"
    },
    {
      "x": -2,
      "y": 34,
      "z": 2,
      "name": "Empty"
    },
    {
      "x": -2,
      "y": -1,
      "z": 3,
      "name": "Wood_Poisoned_Trunk"
    },
    {
      "x": -2,
      "y": 0,
      "z": 3,
      "name": "Wood_Poisoned_Trunk"
    },
    {
      "x": -2,
      "y": 1,
      "z": 3,
      "name": "Wood_Poisoned_Trunk_Full"
    },
    {
      "x": -2,
      "y": 21,
      "z": 3,
      "name": "Empty"
    },
    {
      "x": -2,
      "y": 22,
      "z": 3,
      "name": "Empty"
    },
    {
      "x": -2,
      "y": 24,
      "z": 3,
      "name": "Empty"
    },
    {
      "x": -2,
      "y": 26,
      "z": 3,
      "name": "Empty"
    },
    {
      "x": -2,
      "y": 28,
      "z": 3,
      "name": "Empty"
    },
    {
      "x": -2,
      "y": 34,
      "z": 3,
      "name": "Empty"
    },
    {
      "x": -2,
      "y": 21,
      "z": 4,
      "name": "Empty"
    },
    {
      "x": -2,
      "y": 22,
      "z": 4,
      "name": "Empty"
    },
    {
      "x": -2,
      "y": 28,
      "z": 4,
      "name": "Empty"
    },
    {
      "x": -2,
      "y": 33,
      "z": 4,
      "name": "Empty"
    },
    {
      "x": -2,
      "y": 22,
      "z": 5,
      "name": "Empty"
    },
    {
      "x": -2,
      "y": 27,
      "z": 5,
      "name": "Empty"
    },
    {
      "x": -2,
      "y": 28,
      "z": 5,
      "name": "Empty"
    },
    {
      "x": -2,
      "y": 22,
      "z": 6,
      "name": "Empty"
    },
    {
      "x": -2,
      "y": 22,
      "z": 7,
      "name": "Empty"
    },
    {
      "x": -2,
      "y": 21,
      "z": 8,
      "name": "Empty"
    },
    {
      "x": -1,
      "y": 23,
      "z": -9,
      "name": "Empty"
    },
    {
      "x": -1,
      "y": 24,
      "z": -9,
      "name": "Empty"
    },
    {
      "x": -1,
      "y": 20,
      "z": -8,
      "name": "Empty"
    },
    {
      "x": -1,
      "y": 23,
      "z": -8,
      "name": "Empty"
    },
    {
      "x": -1,
      "y": 24,
      "z": -8,
      "name": "Empty"
    },
    {
      "x": -1,
      "y": 28,
      "z": -8,
      "name": "Empty"
    },
    {
      "x": -1,
      "y": 19,
      "z": -7,
      "name": "Empty"
    },
    {
      "x": -1,
      "y": 20,
      "z": -7,
      "name": "Empty"
    },
    {
      "x": -1,
      "y": 24,
      "z": -7,
      "name": "Empty"
    },
    {
      "x": -1,
      "y": 28,
      "z": -7,
      "name": "Empty"
    },
    {
      "x": -1,
      "y": 32,
      "z": -7,
      "name": "Empty"
    },
    {
      "x": -1,
      "y": 19,
      "z": -6,
      "name": "Empty"
    },
    {
      "x": -1,
      "y": 20,
      "z": -6,
      "name": "Wood_Poisoned_Branch_Long",
      "rotation": 4
    },
    {
      "x": -1,
      "y": 24,
      "z": -6,
      "name": "Empty"
    },
    {
      "x": -1,
      "y": 28,
      "z": -6,
      "name": "Empty"
    },
    {
      "x": -1,
      "y": 32,
      "z": -6,
      "name": "Empty"
    },
    {
      "x": -1,
      "y": 33,
      "z": -6,
      "name": "Empty"
    },
    {
      "x": -1,
      "y": -2,
      "z": -5,
      "name": "Wood_Poisoned_Trunk"
    },
    {
      "x": -1,
      "y": -1,
      "z": -5,
      "name": "Wood_Poisoned_Trunk"
    },
    {
      "x": -1,
      "y": 0,
      "z": -5,
      "name": "Wood_Poisoned_Trunk"
    },
    {
      "x": -1,
      "y": 1,
      "z": -5,
      "name": "Wood_Poisoned_Trunk_Full"
    },
    {
      "x": -1,
      "y": 19,
      "z": -5,
      "name": "Empty"
    },
    {
      "x": -1,
      "y": 20,
      "z": -5,
      "name": "Wood_Poisoned_Trunk_Full"
    },
    {
      "x": -1,
      "y": 24,
      "z": -5,
      "name": "Empty"
    },
    {
      "x": -1,
      "y": 28,
      "z": -5,
      "name": "Wood_Poisoned_Branch_Long",
      "rotation": 4
    },
    {
      "x": -1,
      "y": 33,
      "z": -5,
      "name": "Wood_Poisoned_Branch_Long",
      "rotation": 4
    },
    {
      "x": -1,
      "y": 40,
      "z": -5,
      "name": "Empty"
    },
    {
      "x": -1,
      "y": 0,
      "z": -4,
      "name": "Wood_Poisoned_Trunk"
    },
    {
      "x": -1,
      "y": 1,
      "z": -4,
      "name": "Wood_Poisoned_Trunk"
    },
    {
      "x": -1,
      "y": 2,
      "z": -4,
      "name": "Wood_Poisoned_Trunk"
    },
    {
      "x": -1,
      "y": 3,
      "z": -4,
      "name": "Wood_Poisoned_Trunk"
    },
    {
      "x": -1,
      "y": 4,
      "z": -4,
      "name": "Wood_Poisoned_Trunk"
    },
    {
      "x": -1,
      "y": 5,
      "z": -4,
      "name": "Wood_Poisoned_Trunk"
    },
    {
      "x": -1,
      "y": 6,
      "z": -4,
      "name": "Wood_Poisoned_Trunk_Full"
    },
    {
      "x": -1,
      "y": 7,
      "z": -4,
      "name": "Plant_Vine_Wall_Poisoned",
      "rotation": 2
    },
    {
      "x": -1,
      "y": 8,
      "z": -4,
      "name": "Plant_Vine_Wall_Poisoned",
      "rotation": 2
    },
    {
      "x": -1,
      "y": 9,
      "z": -4,
      "name": "Plant_Vine_Wall_Poisoned",
      "rotation": 2
    },
    {
      "x": -1,
      "y": 13,
      "z": -4,
      "name": "Wood_Crystal_Branch_Short",
      "rotation": 2
    },
    {
      "x": -1,
      "y": 16,
      "z": -4,
      "name": "Wood_Crystal_Branch_Short",
      "rotation": 2
    },
    {
      "x": -1,
      "y": 18,
      "z": -4,
      "name": "Wood_Crystal_Branch_Short",
      "rotation": 2
    },
    {
      "x": -1,
      "y": 19,
      "z": -4,
      "name": "Empty"
    },
    {
      "x": -1,
      "y": 20,
      "z": -4,
      "name": "Wood_Poisoned_Trunk_Full"
    },
    {
      "x": -1,
      "y": 21,
      "z": -4,
      "name": "Empty"
    },
    {
      "x": -1,
      "y": 24,
      "z": -4,
      "name": "Wood_Poisoned_Branch_Long",
      "rotation": 4
    },
    {
      "x": -1,
      "y": 27,
      "z": -4,
      "name": "Empty"
    },
    {
      "x": -1,
      "y": 28,
      "z": -4,
      "name": "Wood_Poisoned_Trunk_Full"
    },
    {
      "x": -1,
      "y": 33,
      "z": -4,
      "name": "Wood_Poisoned_Trunk_Full"
    },
    {
      "x": -1,
      "y": 34,
      "z": -4,
      "name": "Empty"
    },
    {
      "x": -1,
      "y": 37,
      "z": -4,
      "name": "Empty"
    },
    {
      "x": -1,
      "y": 39,
      "z": -4,
      "name": "Empty",
      "rotation": 8
    },
    {
      "x": -1,
      "y": 40,
      "z": -4,
      "name": "Wood_Poisoned_Branch_Long",
      "rotation": 4
    },
    {
      "x": -1,
      "y": 44,
      "z": -4,
      "name": "Empty"
    },
    {
      "x": -1,
      "y": 1,
      "z": -3,
      "name": "Wood_Poisoned_Trunk"
    },
    {
      "x": -1,
      "y": 2,
      "z": -3,
      "name": "Wood_Poisoned_Trunk"
    },
    {
      "x": -1,
      "y": 3,
      "z": -3,
      "name": "Wood_Poisoned_Trunk"
    },
    {
      "x": -1,
      "y": 4,
      "z": -3,
      "name": "Wood_Poisoned_Trunk"
    },
    {
      "x": -1,
      "y": 5,
      "z": -3,
      "name": "Wood_Poisoned_Trunk"
    },
    {
      "x": -1,
      "y": 6,
      "z": -3,
      "name": "Wood_Poisoned_Trunk"
    },
    {
      "x": -1,
      "y": 7,
      "z": -3,
      "name": "Wood_Poisoned_Trunk"
    },
    {
      "x": -1,
      "y": 8,
      "z": -3,
      "name": "Wood_Poisoned_Trunk"
    },
    {
      "x": -1,
      "y": 9,
      "z": -3,
      "name": "Wood_Poisoned_Trunk"
    },
    {
      "x": -1,
      "y": 10,
      "z": -3,
      "name": "Wood_Poisoned_Trunk"
    },
    {
      "x": -1,
      "y": 11,
      "z": -3,
      "name": "Wood_Poisoned_Trunk"
    },
    {
      "x": -1,
      "y": 12,
      "z": -3,
      "name": "Wood_Poisoned_Trunk"
    },
    {
      "x": -1,
      "y": 13,
      "z": -3,
      "name": "Wood_Poisoned_Trunk"
    },
    {
      "x": -1,
      "y": 14,
      "z": -3,
      "name": "Wood_Poisoned_Trunk"
    },
    {
      "x": -1,
      "y": 15,
      "z": -3,
      "name": "Wood_Poisoned_Trunk"
    },
    {
      "x": -1,
      "y": 16,
      "z": -3,
      "name": "Wood_Poisoned_Trunk"
    },
    {
      "x": -1,
      "y": 17,
      "z": -3,
      "name": "Wood_Poisoned_Trunk"
    },
    {
      "x": -1,
      "y": 18,
      "z": -3,
      "name": "Wood_Poisoned_Trunk_Full"
    },
    {
      "x": -1,
      "y": 19,
      "z": -3,
      "name": "Empty"
    },
    {
      "x": -1,
      "y": 20,
      "z": -3,
      "name": "Wood_Poisoned_Trunk_Full"
    },
    {
      "x": -1,
      "y": 21,
      "z": -3,
      "name": "Empty"
    },
    {
      "x": -1,
      "y": 23,
      "z": -3,
      "name": "Empty"
    },
    {
      "x": -1,
      "y": 24,
      "z": -3,
      "name": "Wood_Poisoned_Trunk_Full"
    },
    {
      "x": -1,
      "y": 26,
      "z": -3,
      "name": "Empty"
    },
    {
      "x": -1,
      "y": 27,
      "z": -3,
      "name": "Empty"
    },
    {
      "x": -1,
      "y": 28,
      "z": -3,
      "name": "Wood_Poisoned_Trunk_Full"
    },
    {
      "x": -1,
      "y": 29,
      "z": -3,
      "name": "Empty"
    },
    {
      "x": -1,
      "y": 32,
      "z": -3,
      "name": "Empty"
    },
    {
      "x": -1,
      "y": 33,
      "z": -3,
      "name": "Wood_Poisoned_Trunk_Full"
    },
    {
      "x": -1,
      "y": 34,
      "z": -3,
      "name": "Empty"
    },
    {
      "x": -1,
      "y": 35,
      "z": -3,
      "name": "Empty"
    },
    {
      "x": -1,
      "y": 37,
      "z": -3,
      "name": "Wood_Poisoned_Trunk_Full"
    },
    {
      "x": -1,
      "y": 38,
      "z": -3,
      "name": "Empty"
    },
    {
      "x": -1,
      "y": 40,
      "z": -3,
      "name": "Wood_Poisoned_Trunk_Full"
    },
    {
      "x": -1,
      "y": 41,
      "z": -3,
      "name": "Empty"
    },
    {
      "x": -1,
      "y": 44,
      "z": -3,
      "name": "Wood_Poisoned_Trunk_Full"
    },
    {
      "x": -1,
      "y": 2,
      "z": -2,
      "name": "Wood_Poisoned_Trunk"
    },
    {
      "x": -1,
      "y": 3,
      "z": -2,
      "name": "Wood_Poisoned_Trunk"
    },
    {
      "x": -1,
      "y": 4,
      "z": -2,
      "name": "Wood_Poisoned_Trunk"
    },
    {
      "x": -1,
      "y": 5,
      "z": -2,
      "name": "Wood_Poisoned_Trunk"
    },
    {
      "x": -1,
      "y": 6,
      "z": -2,
      "name": "Wood_Poisoned_Trunk"
    },
    {
      "x": -1,
      "y": 7,
      "z": -2,
      "name": "Wood_Poisoned_Trunk"
    },
    {
      "x": -1,
      "y": 8,
      "z": -2,
      "name": "Wood_Poisoned_Trunk"
    },
    {
      "x": -1,
      "y": 9,
      "z": -2,
      "name": "Wood_Poisoned_Trunk"
    },
    {
      "x": -1,
      "y": 10,
      "z": -2,
      "name": "Wood_Poisoned_Trunk"
    },
    {
      "x": -1,
      "y": 11,
      "z": -2,
      "name": "Wood_Poisoned_Trunk"
    },
    {
      "x": -1,
      "y": 12,
      "z": -2,
      "name": "Wood_Poisoned_Trunk"
    },
    {
      "x": -1,
      "y": 13,
      "z": -2,
      "name": "Wood_Poisoned_Trunk"
    },
    {
      "x": -1,
      "y": 14,
      "z": -2,
      "name": "Wood_Poisoned_Trunk"
    },
    {
      "x": -1,
      "y": 15,
      "z": -2,
      "name": "Wood_Poisoned_Trunk"
    },
    {
      "x": -1,
      "y": 16,
      "z": -2,
      "name": "Wood_Poisoned_Trunk"
    },
    {
      "x": -1,
      "y": 17,
      "z": -2,
      "name": "Wood_Poisoned_Trunk"
    },
    {
      "x": -1,
      "y": 18,
      "z": -2,
      "name": "Wood_Poisoned_Trunk"
    },
    {
      "x": -1,
      "y": 19,
      "z": -2,
      "name": "Wood_Poisoned_Trunk"
    },
    {
      "x": -1,
      "y": 20,
      "z": -2,
      "name": "Wood_Poisoned_Trunk"
    },
    {
      "x": -1,
      "y": 21,
      "z": -2,
      "name": "Wood_Poisoned_Trunk"
    },
    {
      "x": -1,
      "y": 22,
      "z": -2,
      "name": "Wood_Poisoned_Trunk"
    },
    {
      "x": -1,
      "y": 23,
      "z": -2,
      "name": "Wood_Poisoned_Trunk"
    },
    {
      "x": -1,
      "y": 24,
      "z": -2,
      "name": "Wood_Poisoned_Trunk"
    },
    {
      "x": -1,
      "y": 25,
      "z": -2,
      "name": "Wood_Poisoned_Trunk"
    },
    {
      "x": -1,
      "y": 26,
      "z": -2,
      "name": "Wood_Poisoned_Trunk"
    },
    {
      "x": -1,
      "y": 27,
      "z": -2,
      "name": "Wood_Poisoned_Trunk"
    },
    {
      "x": -1,
      "y": 28,
      "z": -2,
      "name": "Wood_Poisoned_Trunk"
    },
    {
      "x": -1,
      "y": 29,
      "z": -2,
      "name": "Wood_Poisoned_Trunk"
    },
    {
      "x": -1,
      "y": 30,
      "z": -2,
      "name": "Wood_Poisoned_Trunk"
    },
    {
      "x": -1,
      "y": 31,
      "z": -2,
      "name": "Wood_Poisoned_Trunk"
    },
    {
      "x": -1,
      "y": 32,
      "z": -2,
      "name": "Wood_Poisoned_Trunk"
    },
    {
      "x": -1,
      "y": 33,
      "z": -2,
      "name": "Wood_Poisoned_Trunk"
    },
    {
      "x": -1,
      "y": 34,
      "z": -2,
      "name": "Wood_Poisoned_Trunk"
    },
    {
      "x": -1,
      "y": 35,
      "z": -2,
      "name": "Wood_Poisoned_Trunk"
    },
    {
      "x": -1,
      "y": 36,
      "z": -2,
      "name": "Wood_Poisoned_Trunk"
    },
    {
      "x": -1,
      "y": 37,
      "z": -2,
      "name": "Wood_Poisoned_Trunk"
    },
    {
      "x": -1,
      "y": 38,
      "z": -2,
      "name": "Wood_Poisoned_Trunk"
    },
    {
      "x": -1,
      "y": 39,
      "z": -2,
      "name": "Wood_Poisoned_Trunk"
    },
    {
      "x": -1,
      "y": 40,
      "z": -2,
      "name": "Wood_Poisoned_Trunk"
    },
    {
      "x": -1,
      "y": 41,
      "z": -2,
      "name": "Wood_Poisoned_Trunk"
    },
    {
      "x": -1,
      "y": 42,
      "z": -2,
      "name": "Wood_Poisoned_Trunk"
    },
    {
      "x": -1,
      "y": 43,
      "z": -2,
      "name": "Wood_Poisoned_Trunk"
    },
    {
      "x": -1,
      "y": 44,
      "z": -2,
      "name": "Wood_Poisoned_Trunk"
    },
    {
      "x": -1,
      "y": 45,
      "z": -2,
      "name": "Wood_Poisoned_Trunk"
    },
    {
      "x": -1,
      "y": 46,
      "z": -2,
      "name": "Wood_Poisoned_Trunk"
    },
    {
      "x": -1,
      "y": 47,
      "z": -2,
      "name": "Wood_Poisoned_Trunk_Full"
    },
    {
      "x": -1,
      "y": 48,
      "z": -2,
      "name": "Empty"
    },
    {
      "x": -1,
      "y": 49,
      "z": -2,
      "name": "Empty"
    },
    {
      "x": -1,
      "y": 50,
      "z": -2,
      "name": "Empty"
    },
    {
      "x": -1,
      "y": 51,
      "z": -2,
      "name": "Empty"
    },
    {
      "x": -1,
      "y": 2,
      "z": -1,
      "name": "Wood_Poisoned_Trunk"
    },
    {
      "x": -1,
      "y": 3,
      "z": -1,
      "name": "Wood_Poisoned_Trunk"
    },
    {
      "x": -1,
      "y": 4,
      "z": -1,
      "name": "Wood_Poisoned_Trunk"
    },
    {
      "x": -1,
      "y": 5,
      "z": -1,
      "name": "Wood_Poisoned_Trunk"
    },
    {
      "x": -1,
      "y": 6,
      "z": -1,
      "name": "Wood_Poisoned_Trunk"
    },
    {
      "x": -1,
      "y": 7,
      "z": -1,
      "name": "Wood_Poisoned_Trunk"
    },
    {
      "x": -1,
      "y": 8,
      "z": -1,
      "name": "Wood_Poisoned_Trunk"
    },
    {
      "x": -1,
      "y": 9,
      "z": -1,
      "name": "Wood_Poisoned_Trunk"
    },
    {
      "x": -1,
      "y": 10,
      "z": -1,
      "name": "Wood_Poisoned_Trunk"
    },
    {
      "x": -1,
      "y": 11,
      "z": -1,
      "name": "Wood_Poisoned_Trunk"
    },
    {
      "x": -1,
      "y": 12,
      "z": -1,
      "name": "Wood_Poisoned_Trunk"
    },
    {
      "x": -1,
      "y": 13,
      "z": -1,
      "name": "Wood_Poisoned_Trunk"
    },
    {
      "x": -1,
      "y": 14,
      "z": -1,
      "name": "Wood_Poisoned_Trunk"
    },
    {
      "x": -1,
      "y": 15,
      "z": -1,
      "name": "Wood_Poisoned_Trunk"
    },
    {
      "x": -1,
      "y": 16,
      "z": -1,
      "name": "Wood_Poisoned_Trunk"
    },
    {
      "x": -1,
      "y": 17,
      "z": -1,
      "name": "Wood_Poisoned_Trunk"
    },
    {
      "x": -1,
      "y": 18,
      "z": -1,
      "name": "Wood_Poisoned_Trunk"
    },
    {
      "x": -1,
      "y": 19,
      "z": -1,
      "name": "Wood_Poisoned_Trunk"
    },
    {
      "x": -1,
      "y": 20,
      "z": -1,
      "name": "Wood_Poisoned_Trunk"
    },
    {
      "x": -1,
      "y": 21,
      "z": -1,
      "name": "Wood_Poisoned_Trunk"
    },
    {
      "x": -1,
      "y": 22,
      "z": -1,
      "name": "Wood_Poisoned_Trunk"
    },
    {
      "x": -1,
      "y": 23,
      "z": -1,
      "name": "Wood_Poisoned_Trunk"
    },
    {
      "x": -1,
      "y": 24,
      "z": -1,
      "name": "Wood_Poisoned_Trunk"
    },
    {
      "x": -1,
      "y": 25,
      "z": -1,
      "name": "Wood_Poisoned_Trunk"
    },
    {
      "x": -1,
      "y": 26,
      "z": -1,
      "name": "Wood_Poisoned_Trunk"
    },
    {
      "x": -1,
      "y": 27,
      "z": -1,
      "name": "Wood_Poisoned_Trunk"
    },
    {
      "x": -1,
      "y": 28,
      "z": -1,
      "name": "Wood_Poisoned_Trunk"
    },
    {
      "x": -1,
      "y": 29,
      "z": -1,
      "name": "Wood_Poisoned_Trunk"
    },
    {
      "x": -1,
      "y": 30,
      "z": -1,
      "name": "Wood_Poisoned_Trunk"
    },
    {
      "x": -1,
      "y": 31,
      "z": -1,
      "name": "Wood_Poisoned_Trunk"
    },
    {
      "x": -1,
      "y": 32,
      "z": -1,
      "name": "Wood_Poisoned_Trunk"
    },
    {
      "x": -1,
      "y": 33,
      "z": -1,
      "name": "Wood_Poisoned_Trunk"
    },
    {
      "x": -1,
      "y": 34,
      "z": -1,
      "name": "Wood_Poisoned_Trunk"
    },
    {
      "x": -1,
      "y": 35,
      "z": -1,
      "name": "Wood_Poisoned_Trunk"
    },
    {
      "x": -1,
      "y": 36,
      "z": -1,
      "name": "Wood_Poisoned_Trunk"
    },
    {
      "x": -1,
      "y": 37,
      "z": -1,
      "name": "Wood_Poisoned_Trunk"
    },
    {
      "x": -1,
      "y": 38,
      "z": -1,
      "name": "Wood_Poisoned_Trunk"
    },
    {
      "x": -1,
      "y": 39,
      "z": -1,
      "name": "Wood_Poisoned_Trunk"
    },
    {
      "x": -1,
      "y": 40,
      "z": -1,
      "name": "Wood_Poisoned_Trunk"
    },
    {
      "x": -1,
      "y": 41,
      "z": -1,
      "name": "Wood_Poisoned_Trunk"
    },
    {
      "x": -1,
      "y": 42,
      "z": -1,
      "name": "Wood_Poisoned_Trunk"
    },
    {
      "x": -1,
      "y": 43,
      "z": -1,
      "name": "Wood_Poisoned_Trunk"
    },
    {
      "x": -1,
      "y": 44,
      "z": -1,
      "name": "Wood_Poisoned_Trunk"
    },
    {
      "x": -1,
      "y": 45,
      "z": -1,
      "name": "Wood_Poisoned_Trunk"
    },
    {
      "x": -1,
      "y": 46,
      "z": -1,
      "name": "Wood_Poisoned_Trunk"
    },
    {
      "x": -1,
      "y": 47,
      "z": -1,
      "name": "Wood_Poisoned_Trunk"
    },
    {
      "x": -1,
      "y": 48,
      "z": -1,
      "name": "Wood_Poisoned_Trunk"
    },
    {
      "x": -1,
      "y": 49,
      "z": -1,
      "name": "Wood_Poisoned_Trunk"
    },
    {
      "x": -1,
      "y": 50,
      "z": -1,
      "name": "Wood_Poisoned_Trunk_Full"
    },
    {
      "x": -1,
      "y": 51,
      "z": -1,
      "name": "Empty"
    },
    {
      "x": -1,
      "y": 52,
      "z": -1,
      "name": "Empty"
    },
    {
      "x": -1,
      "y": 53,
      "z": -1,
      "name": "Empty"
    },
    {
      "x": -1,
      "y": 54,
      "z": -1,
      "name": "Empty"
    },
    {
      "x": -1,
      "y": 55,
      "z": -1,
      "name": "Empty"
    },
    {
      "x": -1,
      "y": -2,
      "z": 0,
      "name": "Wood_Poisoned_Trunk"
    },
    {
      "x": -1,
      "y": -1,
      "z": 0,
      "name": "Wood_Poisoned_Trunk"
    },
    {
      "x": -1,
      "y": 1,
      "z": 0,
      "name": "Wood_Poisoned_Trunk"
    },
    {
      "x": -1,
      "y": 2,
      "z": 0,
      "name": "Wood_Poisoned_Trunk"
    },
    {
      "x": -1,
      "y": 3,
      "z": 0,
      "name": "Wood_Poisoned_Trunk"
    },
    {
      "x": -1,
      "y": 4,
      "z": 0,
      "name": "Wood_Poisoned_Trunk"
    },
    {
      "x": -1,
      "y": 5,
      "z": 0,
      "name": "Wood_Poisoned_Trunk"
    },
    {
      "x": -1,
      "y": 6,
      "z": 0,
      "name": "Wood_Poisoned_Trunk"
    },
    {
      "x": -1,
      "y": 7,
      "z": 0,
      "name": "Wood_Poisoned_Trunk"
    },
    {
      "x": -1,
      "y": 8,
      "z": 0,
      "name": "Wood_Poisoned_Trunk"
    },
    {
      "x": -1,
      "y": 9,
      "z": 0,
      "name": "Wood_Poisoned_Trunk"
    },
    {
      "x": -1,
      "y": 10,
      "z": 0,
      "name": "Wood_Poisoned_Trunk"
    },
    {
      "x": -1,
      "y": 11,
      "z": 0,
      "name": "Wood_Poisoned_Trunk"
    },
    {
      "x": -1,
      "y": 12,
      "z": 0,
      "name": "Wood_Poisoned_Trunk"
    },
    {
      "x": -1,
      "y": 13,
      "z": 0,
      "name": "Wood_Poisoned_Trunk"
    },
    {
      "x": -1,
      "y": 14,
      "z": 0,
      "name": "Wood_Poisoned_Trunk"
    },
    {
      "x": -1,
      "y": 15,
      "z": 0,
      "name": "Wood_Poisoned_Trunk"
    },
    {
      "x": -1,
      "y": 16,
      "z": 0,
      "name": "Wood_Poisoned_Trunk"
    },
    {
      "x": -1,
      "y": 17,
      "z": 0,
      "name": "Wood_Poisoned_Trunk"
    },
    {
      "x": -1,
      "y": 18,
      "z": 0,
      "name": "Wood_Poisoned_Trunk"
    },
    {
      "x": -1,
      "y": 19,
      "z": 0,
      "name": "Wood_Poisoned_Trunk"
    },
    {
      "x": -1,
      "y": 20,
      "z": 0,
      "name": "Wood_Poisoned_Trunk"
    },
    {
      "x": -1,
      "y": 21,
      "z": 0,
      "name": "Wood_Poisoned_Trunk"
    },
    {
      "x": -1,
      "y": 22,
      "z": 0,
      "name": "Wood_Poisoned_Trunk"
    },
    {
      "x": -1,
      "y": 23,
      "z": 0,
      "name": "Wood_Poisoned_Trunk"
    },
    {
      "x": -1,
      "y": 24,
      "z": 0,
      "name": "Wood_Poisoned_Trunk"
    },
    {
      "x": -1,
      "y": 25,
      "z": 0,
      "name": "Wood_Poisoned_Trunk"
    },
    {
      "x": -1,
      "y": 26,
      "z": 0,
      "name": "Wood_Poisoned_Trunk"
    },
    {
      "x": -1,
      "y": 27,
      "z": 0,
      "name": "Wood_Poisoned_Trunk"
    },
    {
      "x": -1,
      "y": 28,
      "z": 0,
      "name": "Wood_Poisoned_Trunk"
    },
    {
      "x": -1,
      "y": 29,
      "z": 0,
      "name": "Wood_Poisoned_Trunk"
    },
    {
      "x": -1,
      "y": 30,
      "z": 0,
      "name": "Wood_Poisoned_Trunk"
    },
    {
      "x": -1,
      "y": 31,
      "z": 0,
      "name": "Wood_Poisoned_Trunk"
    },
    {
      "x": -1,
      "y": 32,
      "z": 0,
      "name": "Wood_Poisoned_Trunk"
    },
    {
      "x": -1,
      "y": 33,
      "z": 0,
      "name": "Wood_Poisoned_Trunk"
    },
    {
      "x": -1,
      "y": 34,
      "z": 0,
      "name": "Wood_Poisoned_Trunk"
    },
    {
      "x": -1,
      "y": 35,
      "z": 0,
      "name": "Wood_Poisoned_Trunk"
    },
    {
      "x": -1,
      "y": 36,
      "z": 0,
      "name": "Wood_Poisoned_Trunk"
    },
    {
      "x": -1,
      "y": 37,
      "z": 0,
      "name": "Wood_Poisoned_Trunk"
    },
    {
      "x": -1,
      "y": 38,
      "z": 0,
      "name": "Wood_Poisoned_Trunk"
    },
    {
      "x": -1,
      "y": 39,
      "z": 0,
      "name": "Wood_Poisoned_Trunk"
    },
    {
      "x": -1,
      "y": 40,
      "z": 0,
      "name": "Wood_Poisoned_Trunk"
    },
    {
      "x": -1,
      "y": 41,
      "z": 0,
      "name": "Wood_Poisoned_Trunk"
    },
    {
      "x": -1,
      "y": 42,
      "z": 0,
      "name": "Wood_Poisoned_Trunk"
    },
    {
      "x": -1,
      "y": 43,
      "z": 0,
      "name": "Wood_Poisoned_Trunk"
    },
    {
      "x": -1,
      "y": 44,
      "z": 0,
      "name": "Wood_Poisoned_Trunk"
    },
    {
      "x": -1,
      "y": 45,
      "z": 0,
      "name": "Wood_Poisoned_Trunk"
    },
    {
      "x": -1,
      "y": 46,
      "z": 0,
      "name": "Wood_Poisoned_Trunk_Full"
    },
    {
      "x": -1,
      "y": 47,
      "z": 0,
      "name": "Empty"
    },
    {
      "x": -1,
      "y": 48,
      "z": 0,
      "name": "Empty"
    },
    {
      "x": -1,
      "y": 49,
      "z": 0,
      "name": "Empty"
    },
    {
      "x": -1,
      "y": 50,
      "z": 0,
      "name": "Empty"
    },
    {
      "x": -1,
      "y": 51,
      "z": 0,
      "name": "Empty"
    },
    {
      "x": -1,
      "y": 52,
      "z": 0,
      "name": "Empty"
    },
    {
      "x": -1,
      "y": 1,
      "z": 1,
      "name": "Wood_Poisoned_Trunk"
    },
    {
      "x": -1,
      "y": 2,
      "z": 1,
      "name": "Wood_Poisoned_Trunk"
    },
    {
      "x": -1,
      "y": 3,
      "z": 1,
      "name": "Wood_Poisoned_Trunk"
    },
    {
      "x": -1,
      "y": 4,
      "z": 1,
      "name": "Wood_Poisoned_Trunk"
    },
    {
      "x": -1,
      "y": 5,
      "z": 1,
      "name": "Wood_Poisoned_Trunk"
    },
    {
      "x": -1,
      "y": 6,
      "z": 1,
      "name": "Wood_Poisoned_Trunk"
    },
    {
      "x": -1,
      "y": 7,
      "z": 1,
      "name": "Wood_Poisoned_Trunk"
    },
    {
      "x": -1,
      "y": 8,
      "z": 1,
      "name": "Wood_Poisoned_Trunk"
    },
    {
      "x": -1,
      "y": 9,
      "z": 1,
      "name": "Wood_Poisoned_Trunk"
    },
    {
      "x": -1,
      "y": 10,
      "z": 1,
      "name": "Wood_Poisoned_Trunk"
    },
    {
      "x": -1,
      "y": 11,
      "z": 1,
      "name": "Wood_Poisoned_Trunk"
    },
    {
      "x": -1,
      "y": 12,
      "z": 1,
      "name": "Wood_Poisoned_Trunk"
    },
    {
      "x": -1,
      "y": 13,
      "z": 1,
      "name": "Wood_Poisoned_Trunk"
    },
    {
      "x": -1,
      "y": 14,
      "z": 1,
      "name": "Wood_Poisoned_Trunk"
    },
    {
      "x": -1,
      "y": 15,
      "z": 1,
      "name": "Wood_Poisoned_Trunk"
    },
    {
      "x": -1,
      "y": 16,
      "z": 1,
      "name": "Wood_Poisoned_Trunk"
    },
    {
      "x": -1,
      "y": 17,
      "z": 1,
      "name": "Wood_Poisoned_Trunk"
    },
    {
      "x": -1,
      "y": 18,
      "z": 1,
      "name": "Wood_Poisoned_Trunk"
    },
    {
      "x": -1,
      "y": 19,
      "z": 1,
      "name": "Wood_Poisoned_Trunk"
    },
    {
      "x": -1,
      "y": 20,
      "z": 1,
      "name": "Wood_Poisoned_Trunk"
    },
    {
      "x": -1,
      "y": 21,
      "z": 1,
      "name": "Wood_Poisoned_Trunk"
    },
    {
      "x": -1,
      "y": 22,
      "z": 1,
      "name": "Wood_Poisoned_Trunk_Full"
    },
    {
      "x": -1,
      "y": 23,
      "z": 1,
      "name": "Empty"
    },
    {
      "x": -1,
      "y": 24,
      "z": 1,
      "name": "Empty"
    },
    {
      "x": -1,
      "y": 26,
      "z": 1,
      "name": "Wood_Poisoned_Trunk_Full"
    },
    {
      "x": -1,
      "y": 28,
      "z": 1,
      "name": "Wood_Poisoned_Trunk_Full"
    },
    {
      "x": -1,
      "y": 29,
      "z": 1,
      "name": "Empty"
    },
    {
      "x": -1,
      "y": 31,
      "z": 1,
      "name": "Empty"
    },
    {
      "x": -1,
      "y": 32,
      "z": 1,
      "name": "Empty"
    },
    {
      "x": -1,
      "y": 34,
      "z": 1,
      "name": "Wood_Poisoned_Trunk_Full"
    },
    {
      "x": -1,
      "y": 35,
      "z": 1,
      "name": "Empty"
    },
    {
      "x": -1,
      "y": 37,
      "z": 1,
      "name": "Empty"
    },
    {
      "x": -1,
      "y": 39,
      "z": 1,
      "name": "Wood_Poisoned_Trunk_Full"
    },
    {
      "x": -1,
      "y": 44,
      "z": 1,
      "name": "Wood_Poisoned_Trunk_Full"
    },
    {
      "x": -1,
      "y": 45,
      "z": 1,
      "name": "Empty"
    },
    {
      "x": -1,
      "y": 46,
      "z": 1,
      "name": "Empty"
    },
    {
      "x": -1,
      "y": 1,
      "z": 2,
      "name": "Wood_Poisoned_Trunk"
    },
    {
      "x": -1,
      "y": 2,
      "z": 2,
      "name": "Wood_Poisoned_Trunk"
    },
    {
      "x": -1,
      "y": 3,
      "z": 2,
      "name": "Wood_Poisoned_Trunk"
    },
    {
      "x": -1,
      "y": 4,
      "z": 2,
      "name": "Wood_Poisoned_Trunk"
    },
    {
      "x": -1,
      "y": 5,
      "z": 2,
      "name": "Wood_Poisoned_Trunk"
    },
    {
      "x": -1,
      "y": 6,
      "z": 2,
      "name": "Wood_Poisoned_Trunk"
    },
    {
      "x": -1,
      "y": 7,
      "z": 2,
      "name": "Wood_Poisoned_Trunk_Full"
    },
    {
      "x": -1,
      "y": 9,
      "z": 2,
      "name": "Plant_Vine_Wall_Poisoned"
    },
    {
      "x": -1,
      "y": 10,
      "z": 2,
      "name": "Plant_Vine_Wall_Poisoned"
    },
    {
      "x": -1,
      "y": 11,
      "z": 2,
      "name": "Plant_Vine_Wall_Poisoned"
    },
    {
      "x": -1,
      "y": 13,
      "z": 2,
      "name": "Wood_Crystal_Branch_Short"
    },
    {
      "x": -1,
      "y": 14,
      "z": 2,
      "name": "Wood_Crystal_Branch_Short"
    },
    {
      "x": -1,
      "y": 16,
      "z": 2,
      "name": "Plant_Vine_Wall_Poisoned"
    },
    {
      "x": -1,
      "y": 17,
      "z": 2,
      "name": "Plant_Vine_Wall_Poisoned"
    },
    {
      "x": -1,
      "y": 18,
      "z": 2,
      "name": "Empty"
    },
    {
      "x": -1,
      "y": 20,
      "z": 2,
      "name": "Empty"
    },
    {
      "x": -1,
      "y": 21,
      "z": 2,
      "name": "Empty"
    },
    {
      "x": -1,
      "y": 22,
      "z": 2,
      "name": "Wood_Poisoned_Trunk_Full"
    },
    {
      "x": -1,
      "y": 23,
      "z": 2,
      "name": "Empty"
    },
    {
      "x": -1,
      "y": 24,
      "z": 2,
      "name": "Empty"
    },
    {
      "x": -1,
      "y": 26,
      "z": 2,
      "name": "Wood_Poisoned_Branch_Long",
      "rotation": 4
    },
    {
      "x": -1,
      "y": 28,
      "z": 2,
      "name": "Wood_Poisoned_Trunk_Full"
    },
    {
      "x": -1,
      "y": 29,
      "z": 2,
      "name": "Empty"
    },
    {
      "x": -1,
      "y": 34,
      "z": 2,
      "name": "Wood_Poisoned_Trunk_Full"
    },
    {
      "x": -1,
      "y": 39,
      "z": 2,
      "name": "Empty"
    },
    {
      "x": -1,
      "y": 44,
      "z": 2,
      "name": "Empty"
    },
    {
      "x": -1,
      "y": 0,
      "z": 3,
      "name": "Wood_Poisoned_Trunk"
    },
    {
      "x": -1,
      "y": 1,
      "z": 3,
      "name": "Wood_Poisoned_Trunk"
    },
    {
      "x": -1,
      "y": 2,
      "z": 3,
      "name": "Wood_Poisoned_Trunk_Full"
    },
    {
      "x": -1,
      "y": 7,
      "z": 3,
      "name": "Wood_Crystal_Branch_Short"
    },
    {
      "x": -1,
      "y": 21,
      "z": 3,
      "name": "Empty"
    },
    {
      "x": -1,
      "y": 22,
      "z": 3,
      "name": "Wood_Poisoned_Trunk_Full"
    },
    {
      "x": -1,
      "y": 23,
      "z": 3,
      "name": "Empty"
    },
    {
      "x": -1,
      "y": 25,
      "z": 3,
      "name": "Empty"
    },
    {
      "x": -1,
      "y": 26,
      "z": 3,
      "name": "Empty"
    },
    {
      "x": -1,
      "y": 28,
      "z": 3,
      "name": "Wood_Poisoned_Branch_Long",
      "rotation": 4
    },
    {
      "x": -1,
      "y": 34,
      "z": 3,
      "name": "Wood_Poisoned_Branch_Long",
      "rotation": 4
    },
    {
      "x": -1,
      "y": 39,
      "z": 3,
      "name": "Empty"
    },
    {
      "x": -1,
      "y": 0,
      "z": 4,
      "name": "Wood_Poisoned_Trunk"
    },
    {
      "x": -1,
      "y": 1,
      "z": 4,
      "name": "Wood_Poisoned_Trunk_Full"
    },
    {
      "x": -1,
      "y": 21,
      "z": 4,
      "name": "Empty"
    },
    {
      "x": -1,
      "y": 22,
      "z": 4,
      "name": "Wood_Poisoned_Trunk_Full"
    },
    {
      "x": -1,
      "y": 25,
      "z": 4,
      "name": "Empty"
    },
    {
      "x": -1,
      "y": 28,
      "z": 4,
      "name": "Empty"
    },
    {
      "x": -1,
      "y": 33,
      "z": 4,
      "name": "Empty"
    },
    {
      "x": -1,
      "y": 34,
      "z": 4,
      "name": "Empty"
    },
    {
      "x": -1,
      "y": 39,
      "z": 4,
      "name": "Empty"
    },
    {
      "x": -1,
      "y": 0,
      "z": 5,
      "name": "Wood_Poisoned_Trunk_Full"
    },
    {
      "x": -1,
      "y": 22,
      "z": 5,
      "name": "Empty"
    },
    {
      "x": -1,
      "y": 27,
      "z": 5,
      "name": "Empty"
    },
    {
      "x": -1,
      "y": 33,
      "z": 5,
      "name": "Empty"
    },
    {
      "x": -1,
      "y": 22,
      "z": 6,
      "name": "Empty"
    },
    {
      "x": -1,
      "y": 27,
      "z": 6,
      "name": "Empty"
    },
    {
      "x": -1,
      "y": 33,
      "z": 6,
      "name": "Empty"
    },
    {
      "x": -1,
      "y": 21,
      "z": 7,
      "name": "Empty"
    },
    {
      "x": -1,
      "y": 22,
      "z": 7,
      "name": "Empty"
    },
    {
      "x": -1,
      "y": 27,
      "z": 7,
      "name": "Empty"
    },
    {
      "x": -1,
      "y": 20,
      "z": 8,
      "name": "Empty"
    },
    {
      "x": -1,
      "y": 21,
      "z": 8,
      "name": "Empty"
    },
    {
      "x": -1,
      "y": 21,
      "z": 9,
      "name": "Empty"
    },
    {
      "x": -1,
      "y": 21,
      "z": 10,
      "name": "Empty"
    },
    {
      "x": 0,
      "y": 20,
      "z": -7,
      "name": "Empty"
    },
    {
      "x": 0,
      "y": 24,
      "z": -7,
      "name": "Empty"
    },
    {
      "x": 0,
      "y": 20,
      "z": -6,
      "name": "Empty"
    },
    {
      "x": 0,
      "y": 24,
      "z": -6,
      "name": "Empty"
    },
    {
      "x": 0,
      "y": 28,
      "z": -6,
      "name": "Empty"
    },
    {
      "x": 0,
      "y": 0,
      "z": -5,
      "name": "Wood_Poisoned_Trunk"
    },
    {
      "x": 0,
      "y": 1,
      "z": -5,
      "name": "Wood_Poisoned_Trunk"
    },
    {
      "x": 0,
      "y": 2,
      "z": -5,
      "name": "Wood_Poisoned_Trunk_Full"
    },
    {
      "x": 0,
      "y": 19,
      "z": -5,
      "name": "Empty"
    },
    {
      "x": 0,
      "y": 20,
      "z": -5,
      "name": "Empty"
    },
    {
      "x": 0,
      "y": 24,
      "z": -5,
      "name": "Empty"
    },
    {
      "x": 0,
      "y": 28,
      "z": -5,
      "name": "Empty"
    },
    {
      "x": 0,
      "y": 33,
      "z": -5,
      "name": "Empty"
    },
    {
      "x": 0,
      "y": 1,
      "z": -4,
      "name": "Wood_Poisoned_Trunk"
    },
    {
      "x": 0,
      "y": 2,
      "z": -4,
      "name": "Wood_Poisoned_Trunk"
    },
    {
      "x": 0,
      "y": 3,
      "z": -4,
      "name": "Wood_Poisoned_Trunk_Full"
    },
    {
      "x": 0,
      "y": 5,
      "z": -4,
      "name": "Wood_Crystal_Branch_Short",
      "rotation": 2
    },
    {
      "x": 0,
      "y": 6,
      "z": -4,
      "name": "Wood_Crystal_Branch_Short",
      "rotation": 2
    },
    {
      "x": 0,
      "y": 18,
      "z": -4,
      "name": "Empty",
      "rotation": 8
    },
    {
      "x": 0,
      "y": 19,
      "z": -4,
      "name": "Empty"
    },
    {
      "x": 0,
      "y": 20,
      "z": -4,
      "name": "Empty"
    },
    {
      "x": 0,
      "y": 24,
      "z": -4,
      "name": "Empty"
    },
    {
      "x": 0,
      "y": 26,
      "z": -4,
      "name": "Empty"
    },
    {
      "x": 0,
      "y": 28,
      "z": -4,
      "name": "Empty"
    },
    {
      "x": 0,
      "y": 32,
      "z": -4,
      "name": "Empty"
    },
    {
      "x": 0,
      "y": 33,
      "z": -4,
      "name": "Empty"
    },
    {
      "x": 0,
      "y": 40,
      "z": -4,
      "name": "Empty"
    },
    {
      "x": 0,
      "y": 1,
      "z": -3,
      "name": "Wood_Poisoned_Trunk"
    },
    {
      "x": 0,
      "y": 2,
      "z": -3,
      "name": "Wood_Poisoned_Trunk"
    },
    {
      "x": 0,
      "y": 3,
      "z": -3,
      "name": "Wood_Poisoned_Trunk"
    },
    {
      "x": 0,
      "y": 4,
      "z": -3,
      "name": "Wood_Poisoned_Trunk"
    },
    {
      "x": 0,
      "y": 5,
      "z": -3,
      "name": "Wood_Poisoned_Trunk"
    },
    {
      "x": 0,
      "y": 6,
      "z": -3,
      "name": "Wood_Poisoned_Trunk"
    },
    {
      "x": 0,
      "y": 7,
      "z": -3,
      "name": "Wood_Poisoned_Trunk"
    },
    {
      "x": 0,
      "y": 8,
      "z": -3,
      "name": "Wood_Poisoned_Trunk"
    },
    {
      "x": 0,
      "y": 9,
      "z": -3,
      "name": "Wood_Poisoned_Trunk_Full"
    },
    {
      "x": 0,
      "y": 10,
      "z": -3,
      "name": "Wood_Crystal_Branch_Short",
      "rotation": 2
    },
    {
      "x": 0,
      "y": 11,
      "z": -3,
      "name": "Wood_Crystal_Branch_Short",
      "rotation": 2
    },
    {
      "x": 0,
      "y": 12,
      "z": -3,
      "name": "Wood_Crystal_Branch_Short",
      "rotation": 2
    },
    {
      "x": 0,
      "y": 13,
      "z": -3,
      "name": "Plant_Vine_Wall_Poisoned",
      "rotation": 1
    },
    {
      "x": 0,
      "y": 15,
      "z": -3,
      "name": "Plant_Vine_Wall_Poisoned",
      "rotation": 1
    },
    {
      "x": 0,
      "y": 17,
      "z": -3,
      "name": "Wood_Crystal_Branch_Short",
      "rotation": 2
    },
    {
      "x": 0,
      "y": 18,
      "z": -3,
      "name": "Wood_Crystal_Branch_Short",
      "rotation": 2
    },
    {
      "x": 0,
      "y": 19,
      "z": -3,
      "name": "Empty"
    },
    {
      "x": 0,
      "y": 20,
      "z": -3,
      "name": "Empty"
    },
    {
      "x": 0,
      "y": 21,
      "z": -3,
      "name": "Empty"
    },
    {
      "x": 0,
      "y": 24,
      "z": -3,
      "name": "Empty"
    },
    {
      "x": 0,
      "y": 26,
      "z": -3,
      "name": "Empty"
    },
    {
      "x": 0,
      "y": 27,
      "z": -3,
      "name": "Empty"
    },
    {
      "x": 0,
      "y": 28,
      "z": -3,
      "name": "Empty"
    },
    {
      "x": 0,
      "y": 29,
      "z": -3,
      "name": "Empty"
    },
    {
      "x": 0,
      "y": 31,
      "z": -3,
      "name": "Empty"
    },
    {
      "x": 0,
      "y": 32,
      "z": -3,
      "name": "Empty"
    },
    {
      "x": 0,
      "y": 33,
      "z": -3,
      "name": "Empty"
    },
    {
      "x": 0,
      "y": 37,
      "z": -3,
      "name": "Empty"
    },
    {
      "x": 0,
      "y": 40,
      "z": -3,
      "name": "Empty"
    },
    {
      "x": 0,
      "y": 44,
      "z": -3,
      "name": "Empty"
    },
    {
      "x": 0,
      "y": 0,
      "z": -2,
      "name": "Wood_Poisoned_Trunk"
    },
    {
      "x": 0,
      "y": 1,
      "z": -2,
      "name": "Wood_Poisoned_Trunk"
    },
    {
      "x": 0,
      "y": 2,
      "z": -2,
      "name": "Wood_Poisoned_Trunk"
    },
    {
      "x": 0,
      "y": 3,
      "z": -2,
      "name": "Wood_Poisoned_Trunk"
    },
    {
      "x": 0,
      "y": 4,
      "z": -2,
      "name": "Wood_Poisoned_Trunk"
    },
    {
      "x": 0,
      "y": 5,
      "z": -2,
      "name": "Wood_Poisoned_Trunk"
    },
    {
      "x": 0,
      "y": 6,
      "z": -2,
      "name": "Wood_Poisoned_Trunk"
    },
    {
      "x": 0,
      "y": 7,
      "z": -2,
      "name": "Wood_Poisoned_Trunk"
    },
    {
      "x": 0,
      "y": 8,
      "z": -2,
      "name": "Wood_Poisoned_Trunk"
    },
    {
      "x": 0,
      "y": 9,
      "z": -2,
      "name": "Wood_Poisoned_Trunk"
    },
    {
      "x": 0,
      "y": 10,
      "z": -2,
      "name": "Wood_Poisoned_Trunk"
    },
    {
      "x": 0,
      "y": 11,
      "z": -2,
      "name": "Wood_Poisoned_Trunk"
    },
    {
      "x": 0,
      "y": 12,
      "z": -2,
      "name": "Wood_Poisoned_Trunk"
    },
    {
      "x": 0,
      "y": 13,
      "z": -2,
      "name": "Wood_Poisoned_Trunk"
    },
    {
      "x": 0,
      "y": 14,
      "z": -2,
      "name": "Wood_Poisoned_Trunk"
    },
    {
      "x": 0,
      "y": 15,
      "z": -2,
      "name": "Wood_Poisoned_Trunk"
    },
    {
      "x": 0,
      "y": 16,
      "z": -2,
      "name": "Wood_Poisoned_Trunk"
    },
    {
      "x": 0,
      "y": 17,
      "z": -2,
      "name": "Wood_Poisoned_Trunk"
    },
    {
      "x": 0,
      "y": 18,
      "z": -2,
      "name": "Wood_Poisoned_Trunk"
    },
    {
      "x": 0,
      "y": 19,
      "z": -2,
      "name": "Wood_Poisoned_Trunk"
    },
    {
      "x": 0,
      "y": 20,
      "z": -2,
      "name": "Wood_Poisoned_Trunk"
    },
    {
      "x": 0,
      "y": 21,
      "z": -2,
      "name": "Wood_Poisoned_Trunk"
    },
    {
      "x": 0,
      "y": 22,
      "z": -2,
      "name": "Wood_Poisoned_Trunk"
    },
    {
      "x": 0,
      "y": 23,
      "z": -2,
      "name": "Wood_Poisoned_Trunk"
    },
    {
      "x": 0,
      "y": 24,
      "z": -2,
      "name": "Wood_Poisoned_Trunk"
    },
    {
      "x": 0,
      "y": 25,
      "z": -2,
      "name": "Wood_Poisoned_Trunk"
    },
    {
      "x": 0,
      "y": 26,
      "z": -2,
      "name": "Wood_Poisoned_Trunk"
    },
    {
      "x": 0,
      "y": 27,
      "z": -2,
      "name": "Wood_Poisoned_Trunk"
    },
    {
      "x": 0,
      "y": 28,
      "z": -2,
      "name": "Wood_Poisoned_Trunk"
    },
    {
      "x": 0,
      "y": 29,
      "z": -2,
      "name": "Wood_Poisoned_Trunk"
    },
    {
      "x": 0,
      "y": 30,
      "z": -2,
      "name": "Wood_Poisoned_Trunk"
    },
    {
      "x": 0,
      "y": 31,
      "z": -2,
      "name": "Wood_Poisoned_Trunk"
    },
    {
      "x": 0,
      "y": 32,
      "z": -2,
      "name": "Wood_Poisoned_Trunk"
    },
    {
      "x": 0,
      "y": 33,
      "z": -2,
      "name": "Wood_Poisoned_Trunk"
    },
    {
      "x": 0,
      "y": 34,
      "z": -2,
      "name": "Wood_Poisoned_Trunk"
    },
    {
      "x": 0,
      "y": 35,
      "z": -2,
      "name": "Wood_Poisoned_Trunk"
    },
    {
      "x": 0,
      "y": 36,
      "z": -2,
      "name": "Wood_Poisoned_Trunk"
    },
    {
      "x": 0,
      "y": 37,
      "z": -2,
      "name": "Wood_Poisoned_Trunk"
    },
    {
      "x": 0,
      "y": 38,
      "z": -2,
      "name": "Wood_Poisoned_Trunk"
    },
    {
      "x": 0,
      "y": 39,
      "z": -2,
      "name": "Wood_Poisoned_Trunk"
    },
    {
      "x": 0,
      "y": 40,
      "z": -2,
      "name": "Wood_Poisoned_Trunk"
    },
    {
      "x": 0,
      "y": 41,
      "z": -2,
      "name": "Wood_Poisoned_Trunk"
    },
    {
      "x": 0,
      "y": 42,
      "z": -2,
      "name": "Wood_Poisoned_Trunk"
    },
    {
      "x": 0,
      "y": 43,
      "z": -2,
      "name": "Wood_Poisoned_Trunk_Full"
    },
    {
      "x": 0,
      "y": 44,
      "z": -2,
      "name": "Empty"
    },
    {
      "x": 0,
      "y": 45,
      "z": -2,
      "name": "Empty"
    },
    {
      "x": 0,
      "y": 46,
      "z": -2,
      "name": "Empty"
    },
    {
      "x": 0,
      "y": 47,
      "z": -2,
      "name": "Empty"
    },
    {
      "x": 0,
      "y": 48,
      "z": -2,
      "name": "Empty"
    },
    {
      "x": 0,
      "y": 49,
      "z": -2,
      "name": "Empty"
    },
    {
      "x": 0,
      "y": 3,
      "z": -1,
      "name": "Wood_Poisoned_Trunk"
    },
    {
      "x": 0,
      "y": 4,
      "z": -1,
      "name": "Wood_Poisoned_Trunk"
    },
    {
      "x": 0,
      "y": 5,
      "z": -1,
      "name": "Wood_Poisoned_Trunk"
    },
    {
      "x": 0,
      "y": 6,
      "z": -1,
      "name": "Wood_Poisoned_Trunk"
    },
    {
      "x": 0,
      "y": 7,
      "z": -1,
      "name": "Wood_Poisoned_Trunk"
    },
    {
      "x": 0,
      "y": 8,
      "z": -1,
      "name": "Wood_Poisoned_Trunk"
    },
    {
      "x": 0,
      "y": 9,
      "z": -1,
      "name": "Wood_Poisoned_Trunk"
    },
    {
      "x": 0,
      "y": 10,
      "z": -1,
      "name": "Wood_Poisoned_Trunk"
    },
    {
      "x": 0,
      "y": 11,
      "z": -1,
      "name": "Wood_Poisoned_Trunk"
    },
    {
      "x": 0,
      "y": 12,
      "z": -1,
      "name": "Wood_Poisoned_Trunk"
    },
    {
      "x": 0,
      "y": 13,
      "z": -1,
      "name": "Wood_Poisoned_Trunk"
    },
    {
      "x": 0,
      "y": 14,
      "z": -1,
      "name": "Wood_Poisoned_Trunk"
    },
    {
      "x": 0,
      "y": 15,
      "z": -1,
      "name": "Wood_Poisoned_Trunk"
    },
    {
      "x": 0,
      "y": 16,
      "z": -1,
      "name": "Wood_Poisoned_Trunk"
    },
    {
      "x": 0,
      "y": 17,
      "z": -1,
      "name": "Wood_Poisoned_Trunk"
    },
    {
      "x": 0,
      "y": 18,
      "z": -1,
      "name": "Wood_Poisoned_Trunk"
    },
    {
      "x": 0,
      "y": 19,
      "z": -1,
      "name": "Wood_Poisoned_Trunk"
    },
    {
      "x": 0,
      "y": 20,
      "z": -1,
      "name": "Wood_Poisoned_Trunk"
    },
    {
      "x": 0,
      "y": 21,
      "z": -1,
      "name": "Wood_Poisoned_Trunk"
    },
    {
      "x": 0,
      "y": 22,
      "z": -1,
      "name": "Wood_Poisoned_Trunk"
    },
    {
      "x": 0,
      "y": 23,
      "z": -1,
      "name": "Wood_Poisoned_Trunk"
    },
    {
      "x": 0,
      "y": 24,
      "z": -1,
      "name": "Wood_Poisoned_Trunk"
    },
    {
      "x": 0,
      "y": 25,
      "z": -1,
      "name": "Wood_Poisoned_Trunk"
    },
    {
      "x": 0,
      "y": 26,
      "z": -1,
      "name": "Wood_Poisoned_Trunk"
    },
    {
      "x": 0,
      "y": 27,
      "z": -1,
      "name": "Wood_Poisoned_Trunk"
    },
    {
      "x": 0,
      "y": 28,
      "z": -1,
      "name": "Wood_Poisoned_Trunk"
    },
    {
      "x": 0,
      "y": 29,
      "z": -1,
      "name": "Wood_Poisoned_Trunk"
    },
    {
      "x": 0,
      "y": 30,
      "z": -1,
      "name": "Wood_Poisoned_Trunk"
    },
    {
      "x": 0,
      "y": 31,
      "z": -1,
      "name": "Wood_Poisoned_Trunk"
    },
    {
      "x": 0,
      "y": 32,
      "z": -1,
      "name": "Wood_Poisoned_Trunk"
    },
    {
      "x": 0,
      "y": 33,
      "z": -1,
      "name": "Wood_Poisoned_Trunk"
    },
    {
      "x": 0,
      "y": 34,
      "z": -1,
      "name": "Wood_Poisoned_Trunk"
    },
    {
      "x": 0,
      "y": 35,
      "z": -1,
      "name": "Wood_Poisoned_Trunk"
    },
    {
      "x": 0,
      "y": 36,
      "z": -1,
      "name": "Wood_Poisoned_Trunk"
    },
    {
      "x": 0,
      "y": 37,
      "z": -1,
      "name": "Wood_Poisoned_Trunk"
    },
    {
      "x": 0,
      "y": 38,
      "z": -1,
      "name": "Wood_Poisoned_Trunk"
    },
    {
      "x": 0,
      "y": 39,
      "z": -1,
      "name": "Wood_Poisoned_Trunk"
    },
    {
      "x": 0,
      "y": 40,
      "z": -1,
      "name": "Wood_Poisoned_Trunk"
    },
    {
      "x": 0,
      "y": 41,
      "z": -1,
      "name": "Wood_Poisoned_Trunk"
    },
    {
      "x": 0,
      "y": 42,
      "z": -1,
      "name": "Wood_Poisoned_Trunk"
    },
    {
      "x": 0,
      "y": 43,
      "z": -1,
      "name": "Wood_Poisoned_Trunk"
    },
    {
      "x": 0,
      "y": 44,
      "z": -1,
      "name": "Wood_Poisoned_Trunk"
    },
    {
      "x": 0,
      "y": 45,
      "z": -1,
      "name": "Wood_Poisoned_Trunk_Full"
    },
    {
      "x": 0,
      "y": 46,
      "z": -1,
      "name": "Empty"
    },
    {
      "x": 0,
      "y": 47,
      "z": -1,
      "name": "Empty"
    },
    {
      "x": 0,
      "y": 48,
      "z": -1,
      "name": "Empty"
    },
    {
      "x": 0,
      "y": 49,
      "z": -1,
      "name": "Empty"
    },
    {
      "x": 0,
      "y": 50,
      "z": -1,
      "name": "Empty"
    },
    {
      "x": 0,
      "y": 51,
      "z": -1,
      "name": "Empty"
    },
    {
      "x": 0,
      "y": 52,
      "z": -1,
      "name": "Empty"
    },
    {
      "x": 0,
      "y": 2,
      "z": 0,
      "name": "Wood_Poisoned_Trunk"
    },
    {
      "x": 0,
      "y": 3,
      "z": 0,
      "name": "Wood_Poisoned_Trunk"
    },
    {
      "x": 0,
      "y": 4,
      "z": 0,
      "name": "Wood_Poisoned_Trunk"
    },
    {
      "x": 0,
      "y": 5,
      "z": 0,
      "name": "Wood_Poisoned_Trunk"
    },
    {
      "x": 0,
      "y": 6,
      "z": 0,
      "name": "Wood_Poisoned_Trunk"
    },
    {
      "x": 0,
      "y": 7,
      "z": 0,
      "name": "Wood_Poisoned_Trunk"
    },
    {
      "x": 0,
      "y": 8,
      "z": 0,
      "name": "Wood_Poisoned_Trunk"
    },
    {
      "x": 0,
      "y": 9,
      "z": 0,
      "name": "Wood_Poisoned_Trunk"
    },
    {
      "x": 0,
      "y": 10,
      "z": 0,
      "name": "Wood_Poisoned_Trunk"
    },
    {
      "x": 0,
      "y": 11,
      "z": 0,
      "name": "Wood_Poisoned_Trunk"
    },
    {
      "x": 0,
      "y": 12,
      "z": 0,
      "name": "Wood_Poisoned_Trunk"
    },
    {
      "x": 0,
      "y": 13,
      "z": 0,
      "name": "Wood_Poisoned_Trunk"
    },
    {
      "x": 0,
      "y": 14,
      "z": 0,
      "name": "Wood_Poisoned_Trunk"
    },
    {
      "x": 0,
      "y": 15,
      "z": 0,
      "name": "Wood_Poisoned_Trunk"
    },
    {
      "x": 0,
      "y": 16,
      "z": 0,
      "name": "Wood_Poisoned_Trunk"
    },
    {
      "x": 0,
      "y": 17,
      "z": 0,
      "name": "Wood_Poisoned_Trunk"
    },
    {
      "x": 0,
      "y": 18,
      "z": 0,
      "name": "Wood_Poisoned_Trunk"
    },
    {
      "x": 0,
      "y": 19,
      "z": 0,
      "name": "Wood_Poisoned_Trunk"
    },
    {
      "x": 0,
      "y": 20,
      "z": 0,
      "name": "Wood_Poisoned_Trunk"
    },
    {
      "x": 0,
      "y": 21,
      "z": 0,
      "name": "Wood_Poisoned_Trunk"
    },
    {
      "x": 0,
      "y": 22,
      "z": 0,
      "name": "Wood_Poisoned_Trunk"
    },
    {
      "x": 0,
      "y": 23,
      "z": 0,
      "name": "Wood_Poisoned_Trunk"
    },
    {
      "x": 0,
      "y": 24,
      "z": 0,
      "name": "Wood_Poisoned_Trunk"
    },
    {
      "x": 0,
      "y": 25,
      "z": 0,
      "name": "Wood_Poisoned_Trunk"
    },
    {
      "x": 0,
      "y": 26,
      "z": 0,
      "name": "Wood_Poisoned_Trunk"
    },
    {
      "x": 0,
      "y": 27,
      "z": 0,
      "name": "Wood_Poisoned_Trunk"
    },
    {
      "x": 0,
      "y": 28,
      "z": 0,
      "name": "Wood_Poisoned_Trunk"
    },
    {
      "x": 0,
      "y": 29,
      "z": 0,
      "name": "Wood_Poisoned_Trunk"
    },
    {
      "x": 0,
      "y": 30,
      "z": 0,
      "name": "Wood_Poisoned_Trunk"
    },
    {
      "x": 0,
      "y": 31,
      "z": 0,
      "name": "Wood_Poisoned_Trunk"
    },
    {
      "x": 0,
      "y": 32,
      "z": 0,
      "name": "Wood_Poisoned_Trunk"
    },
    {
      "x": 0,
      "y": 33,
      "z": 0,
      "name": "Wood_Poisoned_Trunk"
    },
    {
      "x": 0,
      "y": 34,
      "z": 0,
      "name": "Wood_Poisoned_Trunk"
    },
    {
      "x": 0,
      "y": 35,
      "z": 0,
      "name": "Wood_Poisoned_Trunk"
    },
    {
      "x": 0,
      "y": 36,
      "z": 0,
      "name": "Wood_Poisoned_Trunk"
    },
    {
      "x": 0,
      "y": 37,
      "z": 0,
      "name": "Wood_Poisoned_Trunk"
    },
    {
      "x": 0,
      "y": 38,
      "z": 0,
      "name": "Wood_Poisoned_Trunk_Full"
    },
    {
      "x": 0,
      "y": 41,
      "z": 0,
      "name": "Empty"
    },
    {
      "x": 0,
      "y": 42,
      "z": 0,
      "name": "Empty"
    },
    {
      "x": 0,
      "y": 44,
      "z": 0,
      "name": "Empty"
    },
    {
      "x": 0,
      "y": 45,
      "z": 0,
      "name": "Empty"
    },
    {
      "x": 0,
      "y": 46,
      "z": 0,
      "name": "Empty"
    },
    {
      "x": 0,
      "y": 47,
      "z": 0,
      "name": "Empty"
    },
    {
      "x": 0,
      "y": 48,
      "z": 0,
      "name": "Empty"
    },
    {
      "x": 0,
      "y": 1,
      "z": 1,
      "name": "Wood_Poisoned_Trunk"
    },
    {
      "x": 0,
      "y": 2,
      "z": 1,
      "name": "Wood_Poisoned_Trunk"
    },
    {
      "x": 0,
      "y": 3,
