{
  "version": 8,
  "blockIdVersion": 10,
  "anchorX": 0,
  "anchorY": 0,
  "anchorZ": 0,
  "blocks": [
    {
      "x": -8,
      "y": 20,
      "z": 5,
      "name": "Empty"
    },
    {
      "x": -7,
      "y": 16,
      "z": 2,
      "name": "Empty"
    },
    {
      "x": -7,
      "y": 17,
      "z": 2,
      "name": "Empty"
    },
    {
      "x": -7,
      "y": 16,
      "z": 3,
      "name": "Empty"
    },
    {
      "x": -7,
      "y": 17,
      "z": 3,
      "name": "Empty"
    },
    {
      "x": -7,
      "y": 20,
      "z": 5,
      "name": "Empty"
    },
    {
      "x": -7,
      "y": 21,
      "z": 5,
      "name": "Empty"
    },
    {
      "x": -7,
      "y": 20,
      "z": 6,
      "name": "Empty"
    },
    {
      "x": -6,
      "y": 15,
      "z": 2,
      "name": "Empty"
    },
    {
      "x": -6,
      "y": 16,
      "z": 2,
      "name": "Empty"
    },
    {
      "x": -6,
      "y": 15,
      "z": 3,
      "name": "Empty"
    },
    {
      "x": -6,
      "y": 16,
      "z": 3,
      "name": "Wood_Poisoned_Trunk"
    },
    {
      "x": -6,
      "y": 17,
      "z": 3,
      "name": "Wood_Poisoned_Trunk"
    },
    {
      "x": -6,
      "y": 18,
      "z": 3,
      "name": "Wood_Poisoned_Trunk"
    },
    {
      "x": -6,
      "y": 19,
      "z": 3,
      "name": "Wood_Poisoned_Trunk_Full"
    },
    {
      "x": -6,
      "y": 19,
      "z": 4,
      "name": "Wood_Poisoned_Trunk_Full"
    },
    {
      "x": -6,
      "y": 20,
      "z": 4,
      "name": "Wood_Poisoned_Trunk"
    },
    {
      "x": -6,
      "y": 21,
      "z": 4,
      "name": "Wood_Poisoned_Trunk"
    },
    {
      "x": -6,
      "y": 22,
      "z": 4,
      "name": "Wood_Poisoned_Trunk_Full"
    },
    {
      "x": -6,
      "y": 20,
      "z": 5,
      "name": "Empty"
    },
    {
      "x": -5,
      "y": 12,
      "z": 1,
      "name": "Wood_Poisoned_Trunk_Full"
    },
    {
      "x": -5,
      "y": 12,
      "z": 2,
      "name": "Wood_Poisoned_Trunk_Full"
    },
    {
      "x": -5,
      "y": 13,
      "z": 2,
      "name": "Wood_Poisoned_Trunk"
    },
    {
      "x": -5,
      "y": 14,
      "z": 2,
      "name": "Wood_Poisoned_Trunk_Full"
    },
    {
      "x": -5,
      "y": 12,
      "z": 3,
      "name": "Empty"
    },
    {
      "x": -5,
      "y": 13,
      "z": 3,
      "name": "Empty"
    },
    {
      "x": -5,
      "y": 14,
      "z": 3,
      "name": "Wood_Poisoned_Trunk"
    },
    {
      "x": -5,
      "y": 15,
      "z": 3,
      "name": "Wood_Poisoned_Trunk"
    },
    {
      "x": -5,
      "y": 16,
      "z": 3,
      "name": "Wood_Poisoned_Trunk_Full"
    },
    {
      "x": -5,
      "y": 19,
      "z": 3,
      "name": "Empty"
    },
    {
      "x": -5,
      "y": 20,
      "z": 3,
      "name": "Empty"
    },
    {
      "x": -5,
      "y": 19,
      "z": 4,
      "name": "Empty"
    },
    {
      "x": -4,
      "y": 12,
      "z": 1,
      "name": "Wood_Poisoned_Trunk_Full"
    },
    {
      "x": -4,
      "y": 13,
      "z": 2,
      "name": "Empty"
    },
    {
      "x": -4,
      "y": 12,
      "z": 3,
      "name": "Empty"
    },
    {
      "x": -4,
      "y": 13,
      "z": 3,
      "name": "Empty"
    },
    {
      "x": -4,
      "y": 19,
      "z": 3,
      "name": "Empty"
    },
    {
      "x": -4,
      "y": 13,
      "z": 4,
      "name": "Empty"
    },
    {
      "x": -3,
      "y": 16,
      "z": -3,
      "name": "Empty"
    },
    {
      "x": -3,
      "y": 15,
      "z": -2,
      "name": "Empty"
    },
    {
      "x": -3,
      "y": 16,
      "z": -2,
      "name": "Empty"
    },
    {
      "x": -3,
      "y": 19,
      "z": -2,
      "name": "Empty"
    },
    {
      "x": -3,
      "y": 11,
      "z": -1,
      "name": "Wood_Poisoned_Trunk_Full"
    },
    {
      "x": -3,
      "y": 19,
      "z": -1,
      "name": "Empty"
    },
    {
      "x": -3,
      "y": 11,
      "z": 0,
      "name": "Wood_Poisoned_Trunk_Full"
    },
    {
      "x": -3,
      "y": 11,
      "z": 1,
      "name": "Wood_Poisoned_Trunk_Full"
    },
    {
      "x": -3,
      "y": 12,
      "z": 1,
      "name": "Wood_Poisoned_Trunk_Full"
    },
    {
      "x": -3,
      "y": 13,
      "z": 2,
      "name": "Empty"
    },
    {
      "x": -2,
      "y": 16,
      "z": -4,
      "name": "Empty"
    },
    {
      "x": -2,
      "y": 15,
      "z": -3,
      "name": "Empty"
    },
    {
      "x": -2,
      "y": 16,
      "z": -3,
      "name": "Empty"
    },
    {
      "x": -2,
      "y": 19,
      "z": -3,
      "name": "Empty"
    },
    {
      "x": -2,
      "y": 20,
      "z": -3,
      "name": "Empty"
    },
    {
      "x": -2,
      "y": 10,
      "z": -2,
      "name": "Empty"
    },
    {
      "x": -2,
      "y": 11,
      "z": -2,
      "name": "Empty"
    },
    {
      "x": -2,
      "y": 15,
      "z": -2,
      "name": "Empty"
    },
    {
      "x": -2,
      "y": 16,
      "z": -2,
      "name": "Wood_Poisoned_Trunk"
    },
    {
      "x": -2,
      "y": 17,
      "z": -2,
      "name": "Wood_Poisoned_Trunk"
    },
    {
      "x": -2,
      "y": 18,
      "z": -2,
      "name": "Wood_Poisoned_Trunk"
    },
    {
      "x": -2,
      "y": 19,
      "z": -2,
      "name": "Wood_Poisoned_Trunk_Full"
    },
    {
      "x": -2,
      "y": 20,
      "z": -2,
      "name": "Empty"
    },
    {
      "x": -2,
      "y": 21,
      "z": -2,
      "name": "Empty"
    },
    {
      "x": -2,
      "y": 11,
      "z": -1,
      "name": "Wood_Poisoned_Trunk_Full"
    },
    {
      "x": -2,
      "y": 19,
      "z": -1,
      "name": "Empty"
    },
    {
      "x": -2,
      "y": 20,
      "z": -1,
      "name": "Empty"
    },
    {
      "x": -1,
      "y": 13,
      "z": -6,
      "name": "Empty"
    },
    {
      "x": -1,
      "y": 14,
      "z": -6,
      "name": "Empty"
    },
    {
      "x": -1,
      "y": 11,
      "z": -3,
      "name": "Empty"
    },
    {
      "x": -1,
      "y": 12,
      "z": -3,
      "name": "Empty"
    },
    {
      "x": -1,
      "y": 16,
      "z": -3,
      "name": "Empty"
    },
    {
      "x": -1,
      "y": 20,
      "z": -3,
      "name": "Empty"
    },
    {
      "x": -1,
      "y": 10,
      "z": -2,
      "name": "Empty"
    },
    {
      "x": -1,
      "y": 11,
      "z": -2,
      "name": "Empty"
    },
    {
      "x": -1,
      "y": 12,
      "z": -2,
      "name": "Wood_Poisoned_Trunk"
    },
    {
      "x": -1,
      "y": 13,
      "z": -2,
      "name": "Wood_Poisoned_Trunk"
    },
    {
      "x": -1,
      "y": 14,
      "z": -2,
      "name": "Wood_Poisoned_Trunk"
    },
    {
      "x": -1,
      "y": 15,
      "z": -2,
      "name": "Wood_Poisoned_Trunk"
    },
    {
      "x": -1,
      "y": 16,
      "z": -2,
      "name": "Wood_Poisoned_Trunk_Full"
    },
    {
      "x": -1,
      "y": 19,
      "z": -2,
      "name": "Empty"
    },
    {
      "x": -1,
      "y": 20,
      "z": -2,
      "name": "Empty"
    },
    {
      "x": -1,
      "y": -1,
      "z": -1,
      "name": "Wood_Poisoned_Trunk"
    },
    {
      "x": -1,
      "y": 0,
      "z": -1,
      "name": "Wood_Poisoned_Trunk_Full"
    },
    {
      "x": -1,
      "y": 9,
      "z": -1,
      "name": "Wood_Poisoned_Trunk_Full"
    },
    {
      "x": -1,
      "y": 10,
      "z": -1,
      "name": "Wood_Poisoned_Trunk"
    },
    {
      "x": -1,
      "y": 11,
      "z": -1,
      "name": "Wood_Poisoned_Trunk"
    },
    {
      "x": -1,
      "y": 12,
      "z": -1,
      "name": "Wood_Poisoned_Trunk_Full"
    },
    {
      "x": -1,
      "y": -2,
      "z": 0,
      "name": "Wood_Poisoned_Trunk"
    },
    {
      "x": -1,
      "y": -1,
      "z": 0,
      "name": "Wood_Poisoned_Trunk"
    },
    {
      "x": -1,
      "y": 0,
      "z": 0,
      "name": "Wood_Poisoned_Trunk"
    },
    {
      "x": -1,
      "y": 1,
      "z": 0,
      "name": "Wood_Poisoned_Trunk"
    },
    {
      "x": -1,
      "y": 2,
      "z": 0,
      "name": "Wood_Poisoned_Trunk"
    },
    {
      "x": -1,
      "y": 3,
      "z": 0,
      "name": "Wood_Poisoned_Trunk"
    },
    {
      "x": -1,
      "y": 4,
      "z": 0,
      "name": "Wood_Poisoned_Trunk_Full"
    },
    {
      "x": -1,
      "y": 0,
      "z": 1,
      "name": "Wood_Poisoned_Trunk"
    },
    {
      "x": -1,
      "y": 1,
      "z": 1,
      "name": "Wood_Poisoned_Trunk"
    },
    {
      "x": -1,
      "y": 2,
      "z": 1,
      "name": "Wood_Poisoned_Trunk_Full"
    },
    {
      "x": 0,
      "y": 12,
      "z": -7,
      "name": "Empty"
    },
    {
      "x": 0,
      "y": 13,
      "z": -7,
      "name": "Empty"
    },
    {
      "x": 0,
      "y": 10,
      "z": -6,
      "name": "Wood_Poisoned_Trunk_Full"
    },
    {
      "x": 0,
      "y": 11,
      "z": -6,
      "name": "Wood_Poisoned_Trunk"
    },
    {
      "x": 0,
      "y": 12,
      "z": -6,
      "name": "Wood_Poisoned_Trunk"
    },
    {
      "x": 0,
      "y": 13,
      "z": -6,
      "name": "Wood_Poisoned_Trunk_Full"
    },
    {
      "x": 0,
      "y": 14,
      "z": -6,
      "name": "Empty"
    },
    {
      "x": 0,
      "y": 7,
      "z": -5,
      "name": "Wood_Poisoned_Trunk_Full"
    },
    {
      "x": 0,
      "y": 8,
      "z": -5,
      "name": "Wood_Poisoned_Trunk"
    },
    {
      "x": 0,
      "y": 9,
      "z": -5,
      "name": "Wood_Poisoned_Trunk"
    },
    {
      "x": 0,
      "y": 10,
      "z": -5,
      "name": "Wood_Poisoned_Trunk_Full"
    },
    {
      "x": 0,
      "y": 6,
      "z": -4,
      "name": "Wood_Poisoned_Trunk_Full"
    },
    {
      "x": 0,
      "y": 7,
      "z": -4,
      "name": "Wood_Poisoned_Trunk_Full"
    },
    {
      "x": 0,
      "y": 6,
      "z": -3,
      "name": "Wood_Poisoned_Trunk_Full"
    },
    {
      "x": 0,
      "y": 5,
      "z": -2,
      "name": "Wood_Poisoned_Trunk_Full"
    },
    {
      "x": 0,
      "y": 6,
      "z": -2,
      "name": "Wood_Poisoned_Trunk_Full"
    },
    {
      "x": 0,
      "y": 11,
      "z": -2,
      "name": "Empty"
    },
    {
      "x": 0,
      "y": 15,
      "z": -2,
      "name": "Wood_Poisoned_Trunk_Full"
    },
    {
      "x": 0,
      "y": -2,
      "z": -1,
      "name": "Wood_Poisoned_Trunk"
    },
    {
      "x": 0,
      "y": -1,
      "z": -1,
      "name": "Wood_Poisoned_Trunk"
    },
    {
      "x": 0,
      "y": 0,
      "z": -1,
      "name": "Wood_Poisoned_Trunk"
    },
    {
      "x": 0,
      "y": 1,
      "z": -1,
      "name": "Wood_Poisoned_Trunk"
    },
    {
      "x": 0,
      "y": 2,
      "z": -1,
      "name": "Wood_Poisoned_Trunk"
    },
    {
      "x": 0,
      "y": 3,
      "z": -1,
      "name": "Wood_Poisoned_Trunk"
    },
    {
      "x": 0,
      "y": 4,
      "z": -1,
      "name": "Wood_Poisoned_Trunk"
    },
    {
      "x": 0,
      "y": 5,
      "z": -1,
      "name": "Wood_Poisoned_Trunk"
    },
    {
      "x": 0,
      "y": 6,
      "z": -1,
      "name": "Wood_Poisoned_Trunk"
    },
    {
      "x": 0,
      "y": 7,
      "z": -1,
      "name": "Wood_Poisoned_Trunk"
    },
    {
      "x": 0,
      "y": 8,
      "z": -1,
      "name": "Wood_Poisoned_Trunk"
    },
    {
      "x": 0,
      "y": 9,
      "z": -1,
      "name": "Wood_Poisoned_Trunk_Full"
    },
    {
      "x": 0,
      "y": 11,
      "z": -1,
      "name": "Empty"
    },
    {
      "x": 0,
      "y": 0,
      "z": 0,
      "name": "Wood_Poisoned_Trunk"
    },
    {
      "x": 0,
      "y": 1,
      "z": 0,
      "name": "Wood_Poisoned_Trunk"
    },
    {
      "x": 0,
      "y": 2,
      "z": 0,
      "name": "Wood_Poisoned_Trunk"
    },
    {
      "x": 0,
      "y": 3,
      "z": 0,
      "name": "Wood_Poisoned_Trunk"
    },
    {
      "x": 0,
      "y": 4,
      "z": 0,
      "name": "Wood_Poisoned_Trunk"
    },
    {
      "x": 0,
      "y": 5,
      "z": 0,
      "name": "Wood_Poisoned_Trunk"
    },
    {
      "x": 0,
      "y": 6,
      "z": 0,
      "name": "Wood_Poisoned_Trunk"
    },
    {
      "x": 0,
      "y": 7,
      "z": 0,
      "name": "Wood_Poisoned_Trunk"
    },
    {
      "x": 0,
      "y": 8,
      "z": 0,
      "name": "Wood_Poisoned_Trunk_Full"
    },
    {
      "x": 0,
      "y": -1,
      "z": 1,
      "name": "Wood_Poisoned_Trunk"
    },
    {
      "x": 0,
      "y": 0,
      "z": 1,
      "name": "Wood_Poisoned_Trunk"
    },
    {
      "x": 0,
      "y": 1,
      "z": 1,
      "name": "Wood_Poisoned_Trunk"
    },
    {
      "x": 0,
      "y": 2,
      "z": 1,
      "name": "Wood_Poisoned_Trunk"
    },
    {
      "x": 0,
      "y": 3,
      "z": 1,
      "name": "Wood_Poisoned_Trunk"
    },
    {
      "x": 0,
      "y": 4,
      "z": 1,
      "name": "Wood_Poisoned_Trunk"
    },
    {
      "x": 0,
      "y": 5,
      "z": 1,
      "name": "Wood_Poisoned_Trunk"
    },
    {
      "x": 0,
      "y": 6,
      "z": 1,
      "name": "Wood_Poisoned_Trunk"
    },
    {
      "x": 0,
      "y": 7,
      "z": 1,
      "name": "Wood_Poisoned_Trunk"
    },
    {
      "x": 0,
      "y": 8,
      "z": 1,
      "name": "Wood_Poisoned_Trunk"
    },
    {
      "x": 0,
      "y": 9,
      "z": 1,
      "name": "Wood_Poisoned_Trunk"
    },
    {
      "x": 0,
      "y": 10,
      "z": 1,
      "name": "Wood_Poisoned_Trunk"
    },
    {
      "x": 0,
      "y": 11,
      "z": 1,
      "name": "Wood_Poisoned_Trunk_Full"
    },
    {
      "x": 0,
      "y": 7,
      "z": 2,
      "name": "Wood_Poisoned_Trunk_Full"
    },
    {
      "x": 0,
      "y": 7,
      "z": 3,
      "name": "Wood_Poisoned_Trunk_Full"
    },
    {
      "x": 1,
      "y": 22,
      "z": -7,
      "name": "Empty"
    },
    {
      "x": 1,
      "y": 13,
      "z": -6,
      "name": "Empty"
    },
    {
      "x": 1,
      "y": 14,
      "z": -6,
      "name": "Empty"
    },
    {
      "x": 1,
      "y": 22,
      "z": -6,
      "name": "Empty"
    },
    {
      "x": 1,
      "y": 23,
      "z": -6,
      "name": "Empty"
    },
    {
      "x": 1,
      "y": 22,
      "z": -5,
      "name": "Empty"
    },
    {
      "x": 1,
      "y": 23,
      "z": -5,
      "name": "Empty"
    },
    {
      "x": 1,
      "y": 15,
      "z": -3,
      "name": "Empty"
    },
    {
      "x": 1,
      "y": 11,
      "z": -2,
      "name": "Empty"
    },
    {
      "x": 1,
      "y": 15,
      "z": -2,
      "name": "Wood_Poisoned_Trunk_Full"
    },
    {
      "x": 1,
      "y": 0,
      "z": -1,
      "name": "Wood_Poisoned_Trunk"
    },
    {
      "x": 1,
      "y": 1,
      "z": -1,
      "name": "Wood_Poisoned_Trunk"
    },
    {
      "x": 1,
      "y": 2,
      "z": -1,
      "name": "Wood_Poisoned_Trunk"
    },
    {
      "x": 1,
      "y": 3,
      "z": -1,
      "name": "Wood_Poisoned_Trunk"
    },
    {
      "x": 1,
      "y": 4,
      "z": -1,
      "name": "Wood_Poisoned_Trunk"
    },
    {
      "x": 1,
      "y": 5,
      "z": -1,
      "name": "Wood_Poisoned_Trunk"
    },
    {
      "x": 1,
      "y": 6,
      "z": -1,
      "name": "Wood_Poisoned_Trunk_Full"
    },
    {
      "x": 1,
      "y": -1,
      "z": 0,
      "name": "Wood_Poisoned_Trunk"
    },
    {
      "x": 1,
      "y": 0,
      "z": 0,
      "name": "Wood_Poisoned_Trunk"
    },
    {
      "x": 1,
      "y": 1,
      "z": 0,
      "name": "Wood_Poisoned_Trunk"
    },
    {
      "x": 1,
      "y": 2,
      "z": 0,
      "name": "Wood_Poisoned_Trunk"
    },
    {
      "x": 1,
      "y": 3,
      "z": 0,
      "name": "Wood_Poisoned_Trunk"
    },
    {
      "x": 1,
      "y": 4,
      "z": 0,
      "name": "Wood_Poisoned_Trunk"
    },
    {
      "x": 1,
      "y": 5,
      "z": 0,
      "name": "Wood_Poisoned_Trunk"
    },
    {
      "x": 1,
      "y": 6,
      "z": 0,
      "name": "Wood_Poisoned_Trunk"
    },
    {
      "x": 1,
      "y": 7,
      "z": 0,
      "name": "Wood_Poisoned_Trunk"
    },
    {
      "x": 1,
      "y": 8,
      "z": 0,
      "name": "Wood_Poisoned_Trunk_Full"
    },
    {
      "x": 1,
      "y": 11,
      "z": 1,
      "name": "Wood_Poisoned_Trunk_Full"
    },
    {
      "x": 1,
      "y": 12,
      "z": 1,
      "name": "Wood_Poisoned_Trunk"
    },
    {
      "x": 1,
      "y": 13,
      "z": 1,
      "name": "Wood_Poisoned_Trunk"
    },
    {
      "x": 1,
      "y": 14,
      "z": 1,
      "name": "Wood_Poisoned_Trunk_Full"
    },
    {
      "x": 1,
      "y": 14,
      "z": 2,
      "name": "Wood_Poisoned_Trunk_Full"
    },
    {
      "x": 1,
      "y": 16,
      "z": 2,
      "name": "Empty"
    },
    {
      "x": 1,
      "y": 7,
      "z": 3,
      "name": "Wood_Poisoned_Trunk_Full"
    },
    {
      "x": 1,
      "y": 16,
      "z": 3,
      "name": "Empty"
    },
    {
      "x": 1,
      "y": 7,
      "z": 4,
      "name": "Wood_Poisoned_Trunk_Full"
    },
    {
      "x": 1,
      "y": 8,
      "z": 4,
      "name": "Wood_Poisoned_Trunk"
    },
    {
      "x": 1,
      "y": 9,
      "z": 4,
      "name": "Wood_Poisoned_Trunk_Full"
    },
    {
      "x": 1,
      "y": 9,
      "z": 5,
      "name": "Wood_Poisoned_Trunk_Full"
    },
    {
      "x": 1,
      "y": 10,
      "z": 5,
      "name": "Empty"
    },
    {
      "x": 1,
      "y": 11,
      "z": 5,
      "name": "Empty"
    },
    {
      "x": 1,
      "y": 10,
      "z": 6,
      "name": "Empty"
    },
    {
      "x": 2,
      "y": 22,
      "z": -6,
      "name": "Empty"
    },
    {
      "x": 2,
      "y": 23,
      "z": -6,
      "name": "Empty"
    },
    {
      "x": 2,
      "y": 21,
      "z": -5,
      "name": "Wood_Poisoned_Trunk_Full"
    },
    {
      "x": 2,
      "y": 22,
      "z": -5,
      "name": "Wood_Poisoned_Trunk"
    },
    {
      "x": 2,
      "y": 23,
      "z": -5,
      "name": "Wood_Poisoned_Trunk_Full"
    },
    {
      "x": 2,
      "y": 24,
      "z": -5,
      "name": "Empty"
    },
    {
      "x": 2,
      "y": 21,
      "z": -4,
      "name": "Wood_Poisoned_Trunk_Full"
    },
    {
      "x": 2,
      "y": 23,
      "z": -4,
      "name": "Empty"
    },
    {
      "x": 2,
      "y": 14,
      "z": -3,
      "name": "Empty"
    },
    {
      "x": 2,
      "y": 15,
      "z": -3,
      "name": "Empty"
    },
    {
      "x": 2,
      "y": 18,
      "z": -3,
      "name": "Empty"
    },
    {
      "x": 2,
      "y": 20,
      "z": -3,
      "name": "Wood_Poisoned_Trunk_Full"
    },
    {
      "x": 2,
      "y": 21,
      "z": -3,
      "name": "Wood_Poisoned_Trunk_Full"
    },
    {
      "x": 2,
      "y": 14,
      "z": -2,
      "name": "Empty"
    },
    {
      "x": 2,
      "y": 15,
      "z": -2,
      "name": "Wood_Poisoned_Trunk"
    },
    {
      "x": 2,
      "y": 16,
      "z": -2,
      "name": "Wood_Poisoned_Trunk"
    },
    {
      "x": 2,
      "y": 17,
      "z": -2,
      "name": "Wood_Poisoned_Trunk"
    },
    {
      "x": 2,
      "y": 18,
      "z": -2,
      "name": "Wood_Poisoned_Trunk"
    },
    {
      "x": 2,
      "y": 19,
      "z": -2,
      "name": "Wood_Poisoned_Trunk"
    },
    {
      "x": 2,
      "y": 20,
      "z": -2,
      "name": "Wood_Poisoned_Trunk_Full"
    },
    {
      "x": 2,
      "y": 4,
      "z": 0,
      "name": "Wood_Poisoned_Trunk_Full"
    },
    {
      "x": 2,
      "y": 5,
      "z": 0,
      "name": "Wood_Poisoned_Trunk"
    },
    {
      "x": 2,
      "y": 6,
      "z": 0,
      "name": "Wood_Poisoned_Trunk"
    },
    {
      "x": 2,
      "y": 7,
      "z": 0,
      "name": "Wood_Poisoned_Trunk_Full"
    },
    {
      "x": 2,
      "y": 14,
      "z": 2,
      "name": "Wood_Poisoned_Trunk_Full"
    },
    {
      "x": 2,
      "y": 15,
      "z": 2,
      "name": "Wood_Poisoned_Trunk"
    },
    {
      "x": 2,
      "y": 16,
      "z": 2,
      "name": "Wood_Poisoned_Trunk"
    },
    {
      "x": 2,
      "y": 17,
      "z": 2,
      "name": "Wood_Poisoned_Trunk"
    },
    {
      "x": 2,
      "y": 18,
      "z": 2,
      "name": "Wood_Poisoned_Trunk_Full"
    },
    {
      "x": 2,
      "y": 16,
      "z": 3,
      "name": "Empty"
    },
    {
      "x": 2,
      "y": 17,
      "z": 3,
      "name": "Empty"
    },
    {
      "x": 2,
      "y": 10,
      "z": 4,
      "name": "Empty"
    },
    {
      "x": 2,
      "y": 11,
      "z": 4,
      "name": "Empty"
    },
    {
      "x": 2,
      "y": 9,
      "z": 5,
      "name": "Wood_Poisoned_Trunk_Full"
    },
    {
      "x": 2,
      "y": 10,
      "z": 5,
      "name": "Wood_Poisoned_Trunk"
    },
    {
      "x": 2,
      "y": 11,
      "z": 5,
      "name": "Wood_Poisoned_Trunk_Full"
    },
    {
      "x": 2,
      "y": 10,
      "z": 6,
      "name": "Empty"
    },
    {
      "x": 2,
      "y": 11,
      "z": 6,
      "name": "Wood_Poisoned_Trunk"
    },
    {
      "x": 2,
      "y": 12,
      "z": 6,
      "name": "Wood_Poisoned_Trunk"
    },
    {
      "x": 2,
      "y": 13,
      "z": 6,
      "name": "Wood_Poisoned_Trunk_Full"
    },
    {
      "x": 2,
      "y": 14,
      "z": 6,
      "name": "Empty"
    },
    {
      "x": 2,
      "y": 15,
      "z": 6,
      "name": "Empty"
    },
    {
      "x": 3,
      "y": 22,
      "z": -7,
      "name": "Empty"
    },
    {
      "x": 3,
      "y": 22,
      "z": -6,
      "name": "Empty"
    },
    {
      "x": 3,
      "y": 23,
      "z": -6,
      "name": "Empty"
    },
    {
      "x": 3,
      "y": 24,
      "z": -5,
      "name": "Empty"
    },
    {
      "x": 3,
      "y": 24,
      "z": -4,
      "name": "Empty"
    },
    {
      "x": 3,
      "y": 17,
      "z": -3,
      "name": "Wood_Poisoned_Trunk_Full"
    },
    {
      "x": 3,
      "y": 18,
      "z": -3,
      "name": "Empty"
    },
    {
      "x": 3,
      "y": 17,
      "z": -2,
      "name": "Wood_Poisoned_Trunk_Full"
    },
    {
      "x": 3,
      "y": 18,
      "z": -2,
      "name": "Empty"
    },
    {
      "x": 3,
      "y": 6,
      "z": 0,
      "name": "Wood_Poisoned_Trunk_Full"
    },
    {
      "x": 3,
      "y": 7,
      "z": 0,
      "name": "Wood_Poisoned_Trunk"
    },
    {
      "x": 3,
      "y": 8,
      "z": 0,
      "name": "Wood_Poisoned_Trunk_Full"
    },
    {
      "x": 3,
      "y": 18,
      "z": 2,
      "name": "Wood_Poisoned_Trunk_Full"
    },
    {
      "x": 3,
      "y": 19,
      "z": 2,
      "name": "Wood_Poisoned_Trunk"
    },
    {
      "x": 3,
      "y": 20,
      "z": 2,
      "name": "Wood_Poisoned_Trunk"
    },
    {
      "x": 3,
      "y": 21,
      "z": 2,
      "name": "Wood_Poisoned_Trunk_Full"
    },
    {
      "x": 3,
      "y": 24,
      "z": 2,
      "name": "Empty"
    },
    {
      "x": 3,
      "y": 25,
      "z": 2,
      "name": "Empty"
    },
    {
      "x": 3,
      "y": 20,
      "z": 3,
      "name": "Empty"
    },
    {
      "x": 3,
      "y": 21,
      "z": 3,
      "name": "Empty"
    },
    {
      "x": 3,
      "y": 24,
      "z": 3,
      "name": "Empty"
    },
    {
      "x": 3,
      "y": 11,
      "z": 4,
      "name": "Empty"
    },
    {
      "x": 3,
      "y": 9,
      "z": 5,
      "name": "Empty"
    },
    {
      "x": 3,
      "y": 10,
      "z": 5,
      "name": "Empty"
    },
    {
      "x": 3,
      "y": 11,
      "z": 5,
      "name": "Empty"
    },
    {
      "x": 3,
      "y": 15,
      "z": 5,
      "name": "Empty"
    },
    {
      "x": 3,
      "y": 13,
      "z": 6,
      "name": "Wood_Poisoned_Trunk_Full"
    },
    {
      "x": 3,
      "y": 14,
      "z": 6,
      "name": "Wood_Poisoned_Trunk"
    },
    {
      "x": 3,
      "y": 15,
      "z": 6,
      "name": "Wood_Poisoned_Trunk"
    },
    {
      "x": 3,
      "y": 16,
      "z": 6,
      "name": "Wood_Poisoned_Trunk_Full"
    },
    {
      "x": 3,
      "y": 15,
      "z": 7,
      "name": "Empty"
    },
    {
      "x": 3,
      "y": 16,
      "z": 7,
      "name": "Wood_Poisoned_Trunk"
    },
    {
      "x": 3,
      "y": 17,
      "z": 7,
      "name": "Wood_Poisoned_Trunk"
    },
    {
      "x": 3,
      "y": 18,
      "z": 7,
      "name": "Wood_Poisoned_Trunk_Full"
    },
    {
      "x": 3,
      "y": 15,
      "z": 8,
      "name": "Empty"
    },
    {
      "x": 4,
      "y": 17,
      "z": -3,
      "name": "Wood_Poisoned_Trunk_Full"
    },
    {
      "x": 4,
      "y": 18,
      "z": -3,
      "name": "Wood_Poisoned_Trunk_Full"
    },
    {
      "x": 4,
      "y": 8,
      "z": -1,
      "name": "Empty"
    },
    {
      "x": 4,
      "y": 9,
      "z": -1,
      "name": "Empty"
    },
    {
      "x": 4,
      "y": 7,
      "z": 0,
      "name": "Empty"
    },
    {
      "x": 4,
      "y": 8,
      "z": 0,
      "name": "Wood_Poisoned_Trunk_Full"
    },
    {
      "x": 4,
      "y": 9,
      "z": 0,
      "name": "Empty"
    },
    {
      "x": 4,
      "y": 8,
      "z": 1,
      "name": "Empty"
    },
    {
      "x": 4,
      "y": 9,
      "z": 1,
      "name": "Empty"
    },
    {
      "x": 4,
      "y": 24,
      "z": 1,
      "name": "Empty"
    },
    {
      "x": 4,
      "y": 25,
      "z": 1,
      "name": "Empty"
    },
    {
      "x": 4,
      "y": 20,
      "z": 2,
      "name": "Empty"
    },
    {
      "x": 4,
      "y": 21,
      "z": 2,
      "name": "Wood_Poisoned_Trunk"
    },
    {
      "x": 4,
      "y": 22,
      "z": 2,
      "name": "Wood_Poisoned_Trunk"
    },
    {
      "x": 4,
      "y": 23,
      "z": 2,
      "name": "Wood_Poisoned_Trunk"
    },
    {
      "x": 4,
      "y": 24,
      "z": 2,
      "name": "Wood_Poisoned_Trunk"
    },
    {
      "x": 4,
      "y": 25,
      "z": 2,
      "name": "Empty"
    },
    {
      "x": 4,
      "y": 20,
      "z": 3,
      "name": "Empty"
    },
    {
      "x": 4,
      "y": 24,
      "z": 3,
      "name": "Empty"
    },
    {
      "x": 4,
      "y": 14,
      "z": 6,
      "name": "Empty"
    },
    {
      "x": 4,
      "y": 15,
      "z": 6,
      "name": "Empty"
    },
    {
      "x": 4,
      "y": 14,
      "z": 7,
      "name": "Empty"
    },
    {
      "x": 4,
      "y": 15,
      "z": 7,
      "name": "Empty"
    },
    {
      "x": 5,
      "y": 13,
      "z": -4,
      "name": "Empty"
    },
    {
      "x": 5,
      "y": 18,
      "z": -3,
      "name": "Wood_Poisoned_Trunk_Full"
    },
    {
      "x": 5,
      "y": 8,
      "z": -1,
      "name": "Empty"
    },
    {
      "x": 5,
      "y": 7,
      "z": 0,
      "name": "Empty"
    },
    {
      "x": 5,
      "y": 8,
      "z": 0,
      "name": "Wood_Poisoned_Trunk"
    },
    {
      "x": 5,
      "y": 9,
      "z": 0,
      "name": "Wood_Poisoned_Trunk_Full"
    },
    {
      "x": 5,
      "y": 8,
      "z": 1,
      "name": "Empty"
    },
    {
      "x": 5,
      "y": 24,
      "z": 1,
      "name": "Empty"
    },
    {
      "x": 5,
      "y": 23,
      "z": 2,
      "name": "Empty"
    },
    {
      "x": 5,
      "y": 24,
      "z": 2,
      "name": "Empty"
    },
    {
      "x": 6,
      "y": 14,
      "z": -7,
      "name": "Empty"
    },
    {
      "x": 6,
      "y": 13,
      "z": -6,
      "name": "Empty"
    },
    {
      "x": 6,
      "y": 14,
      "z": -6,
      "name": "Empty"
    },
    {
      "x": 6,
      "y": 12,
      "z": -5,
      "name": "Empty"
    },
    {
      "x": 6,
      "y": 13,
      "z": -5,
      "name": "Empty"
    },
    {
      "x": 6,
      "y": 14,
      "z": -5,
      "name": "Wood_Poisoned_Trunk"
    },
    {
      "x": 6,
      "y": 15,
      "z": -5,
      "name": "Wood_Poisoned_Trunk"
    },
    {
      "x": 6,
      "y": 16,
      "z": -5,
      "name": "Wood_Poisoned_Trunk_Full"
    },
    {
      "x": 6,
      "y": 12,
      "z": -4,
      "name": "Wood_Poisoned_Trunk_Full"
    },
    {
      "x": 6,
      "y": 13,
      "z": -4,
      "name": "Wood_Poisoned_Trunk"
    },
    {
      "x": 6,
      "y": 14,
      "z": -4,
      "name": "Wood_Poisoned_Trunk_Full"
    },
    {
      "x": 6,
      "y": 18,
      "z": -4,
      "name": "Empty"
    },
    {
      "x": 6,
      "y": 11,
      "z": -3,
      "name": "Wood_Poisoned_Trunk_Full"
    },
    {
      "x": 6,
      "y": 12,
      "z": -3,
      "name": "Wood_Poisoned_Trunk_Full"
    },
    {
      "x": 6,
      "y": 18,
      "z": -3,
      "name": "Wood_Poisoned_Trunk_Full"
    },
    {
      "x": 6,
      "y": 19,
      "z": -3,
      "name": "Empty"
    },
    {
      "x": 6,
      "y": 11,
      "z": -2,
      "name": "Wood_Poisoned_Trunk_Full"
    },
    {
      "x": 6,
      "y": 11,
      "z": -1,
      "name": "Wood_Poisoned_Trunk_Full"
    },
    {
      "x": 6,
      "y": 8,
      "z": 0,
      "name": "Empty"
    },
    {
      "x": 6,
      "y": 9,
      "z": 0,
      "name": "Wood_Poisoned_Trunk"
    },
    {
      "x": 6,
      "y": 10,
      "z": 0,
      "name": "Wood_Poisoned_Trunk"
    },
    {
      "x": 6,
      "y": 11,
      "z": 0,
      "name": "Wood_Poisoned_Trunk"
    },
    {
      "x": 6,
      "y": 12,
      "z": 0,
      "name": "Wood_Poisoned_Trunk_Full"
    },
    {
      "x": 6,
      "y": 8,
      "z": 1,
      "name": "Empty"
    },
    {
      "x": 7,
      "y": 13,
      "z": -6,
      "name": "Empty"
    },
    {
      "x": 7,
      "y": 14,
      "z": -6,
      "name": "Empty"
    },
    {
      "x": 7,
      "y": 12,
      "z": -5,
      "name": "Empty"
    },
    {
      "x": 7,
      "y": 13,
      "z": -5,
      "name": "Empty"
    },
    {
      "x": 7,
      "y": 13,
      "z": -4,
      "name": "Empty"
    },
    {
      "x": 7,
      "y": 19,
      "z": -4,
      "name": "Empty"
    },
    {
      "x": 7,
      "y": 18,
      "z": -3,
      "name": "Wood_Poisoned_Trunk_Full"
    },
    {
      "x": 7,
      "y": 19,
      "z": -3,
      "name": "Wood_Poisoned_Trunk_Full"
    },
    {
      "x": 7,
      "y": 14,
      "z": -1,
      "name": "Empty"
    },
    {
      "x": 7,
      "y": 12,
      "z": 0,
      "name": "Wood_Poisoned_Trunk_Full"
    },
    {
      "x": 7,
      "y": 13,
      "z": 0,
      "name": "Wood_Poisoned_Trunk"
    },
    {
      "x": 7,
      "y": 14,
      "z": 0,
      "name": "Wood_Poisoned_Trunk"
    },
    {
      "x": 7,
      "y": 15,
      "z": 0,
      "name": "Wood_Poisoned_Trunk_Full"
    },
    {
      "x": 7,
      "y": 18,
      "z": 0,
      "name": "Empty"
    },
    {
      "x": 7,
      "y": 13,
      "z": 1,
      "name": "Empty"
    },
    {
      "x": 7,
      "y": 14,
      "z": 1,
      "name": "Empty"
    },
    {
      "x": 7,
      "y": 15,
      "z": 1,
      "name": "Wood_Poisoned_Trunk"
    },
    {
      "x": 7,
      "y": 16,
      "z": 1,
      "name": "Wood_Poisoned_Trunk"
    },
    {
      "x": 7,
      "y": 17,
      "z": 1,
      "name": "Wood_Poisoned_Trunk_Full"
    },
    {
      "x": 7,
      "y": 18,
      "z": 1,
      "name": "Empty"
    },
    {
      "x": 8,
      "y": 14,
      "z": -1,
      "name": "Empty"
    },
    {
      "x": 8,
      "y": 14,
      "z": 0,
      "name": "Empty"
    },
    {
      "x": 8,
      "y": 15,
      "z": 0,
      "name": "Empty"
    },
    {
      "x": 8,
      "y": 17,
      "z": 0,
      "name": "Empty"
    },
    {
      "x": 8,
      "y": 18,
      "z": 0,
      "name": "Empty"
    },
    {
      "x": 8,
      "y": 14,
      "z": 1,
      "name": "Empty"
    },
    {
      "x": 8,
      "y": 15,
      "z": 1,
      "name": "Empty"
    },
    {
      "x": 8,
      "y": 17,
      "z": 1,
      "name": "Wood_Poisoned_Trunk"
    },
    {
      "x": 8,
      "y": 18,
      "z": 1,
      "name": "Wood_Poisoned_Trunk"
    },
    {
      "x": 8,
      "y": 19,
      "z": 1,
      "name": "Wood_Poisoned_Trunk"
    },
    {
      "x": 8,
      "y": 20,
      "z": 1,
      "name": "Wood_Poisoned_Trunk_Full"
    },
    {
      "x": 8,
      "y": 15,
      "z": 2,
      "name": "Empty"
    },
    {
      "x": 8,
      "y": 18,
      "z": 2,
      "name": "Empty"
    },
    {
      "x": 9,
      "y": 18,
      "z": 1,
      "name": "Empty"
    },
    {
      "x": 9,
      "y": 18,
      "z": 2,
      "name": "Empty"
    },
    {
      "x": 9,
      "y": 19,
      "z": 2,
      "name": "Empty"
    }
  ]
}
